
-- Schematic file format version 4

local mts_save = function(name, schematic)
	local s = minetest.serialize_schematic(schematic, mts, {})
	local path = minetest.get_modpath("saveschems") .. "/schematics"
	local filename = path .. "/" .. name .. ".mts"
	filename = filename:gsub("\"", "\\\""):gsub("\\", "\\\\")
	local file, err = io.open(filename, "wb")
	if err == nil then
		file:write(s)
		file:flush()
		file:close()
	end
end


local A = {name="air", prob=0}
local T = {name="default:aspen_tree", prob=255, force_place = true}
local B = {name="default:aspen_tree", prob=255}
local L = {name="default:aspen_leaves", prob=255}
local O = {name="default:aspen_leaves", prob=127}

mts_save("aspen_tree", {
	size = { x = 5, y = 10, z = 5 },
	data = {
		A, A, A, A, A,
		A, A, A, A, A,
		A, A, A, A, A,
		A, A, A, A, A,
		A, A, A, A, A,
		A, A, L, A, A,
		A, L, L, L, A,
		O, L, L, L, O,
		O, L, A, L, O,
		A, A, A, A, A,

		A, A, A, A, A,
		A, A, A, A, A,
		A, A, A, A, A,
		A, A, O, A, A,
		A, A, L, A, A,
		A, L, L, L, A,
		L, L, L, L, L,
		L, L, L, L, L,
		L, L, L, L, L,
		A, O, L, O, A,

		A, A, A, A, A,
		A, A, T, A, A,
		A, A, T, A, A,
		A, O, T, O, A,
		A, L, T, L, A,
		L, L, T, L, L,
		L, L, T, L, L,
		L, L, L, L, L,
		A, L, L, L, A,
		A, L, L, L, A,

		A, A, A, A, A,
		A, A, A, A, A,
		A, A, A, A, A,
		A, A, O, A, A,
		A, A, L, A, A,
		A, L, L, L, A,
		L, L, L, L, L,
		L, L, L, L, L,
		L, L, L, L, L,
		A, O, L, O, A,

		A, A, A, A, A,
		A, A, A, A, A,
		A, A, A, A, A,
		A, A, A, A, A,
		A, A, A, A, A,
		A, A, L, A, A,
		A, L, L, L, A,
		O, L, L, L, O,
		O, L, A, L, O,
		A, A, A, A, A,
	},
	yslice_prob = {
		{ypos=2, prob=191},
		{ypos=7, prob=191},
	},
})

mts_save("aspen_tree_from_sapling", {
	size = { x = 5, y = 10, z = 5 },
	data = {
		A, A, A, A, A,
		A, A, A, A, A,
		A, A, A, A, A,
		A, A, A, A, A,
		A, A, A, A, A,
		A, A, L, A, A,
		A, L, L, L, A,
		O, L, L, L, O,
		O, L, A, L, O,
		A, A, A, A, A,

		A, A, A, A, A,
		A, A, A, A, A,
		A, A, A, A, A,
		A, A, O, A, A,
		A, A, L, A, A,
		A, L, L, L, A,
		L, L, L, L, L,
		L, L, L, L, L,
		L, L, L, L, L,
		A, O, L, O, A,

		A, A, A, A, A,
		A, A, T, A, A,
		A, A, B, A, A,
		A, O, B, O, A,
		A, L, B, L, A,
		L, L, B, L, L,
		L, L, B, L, L,
		L, L, L, L, L,
		A, L, L, L, A,
		A, L, L, L, A,

		A, A, A, A, A,
		A, A, A, A, A,
		A, A, A, A, A,
		A, A, O, A, A,
		A, A, L, A, A,
		A, L, L, L, A,
		L, L, L, L, L,
		L, L, L, L, L,
		L, L, L, L, L,
		A, O, L, O, A,

		A, A, A, A, A,
		A, A, A, A, A,
		A, A, A, A, A,
		A, A, A, A, A,
		A, A, A, A, A,
		A, A, L, A, A,
		A, L, L, L, A,
		O, L, L, L, O,
		O, L, A, L, O,
		A, A, A, A, A,
	},
	yslice_prob = {
		{ypos=2, prob=191},
		{ypos=7, prob=191},
	},
})

-- Apple tree
mts_save("apple_tree", {
	size = {x=5, y=7, z=5},
	data = {-- -2

		{name="air", prob=0},
		{name="air", prob=0},
		{name="air", prob=0},
		{name="air", prob=0},
		{name="air", prob=0},

		{name="air", prob=0},
		{name="air", prob=0},
		{name="air", prob=0},
		{name="air", prob=0},
		{name="air", prob=0},

		{name="air", prob=0},
		{name="air", prob=0},
		{name="air", prob=0},
		{name="air", prob=0},
		{name="air", prob=0},

		{name="air", prob=0},
		{name="air", prob=0},
		{name="air", prob=0},
		{name="air", prob=0},
		{name="air", prob=0},

		{name="default:leaves", prob=191},
		{name="default:leaves", prob=223},
		{name="default:leaves", prob=223},
		{name="default:leaves", prob=223},
		{name="default:leaves", prob=191},

		{name="default:leaves", prob=191},
		{name="default:leaves", prob=223},
		{name="default:leaves", prob=223},
		{name="default:leaves", prob=223},
		{name="default:leaves", prob=191},

		{name="air", prob=0},
		{name="air", prob=0},
		{name="air", prob=0},
		{name="air", prob=0},
		{name="air", prob=0},

		-- -1

		{name="air", prob=0},
		{name="air", prob=0},
		{name="air", prob=0},
		{name="air", prob=0},
		{name="air", prob=0},

		{name="air", prob=0},
		{name="air", prob=0},
		{name="air", prob=0},
		{name="air", prob=0},
		{name="air", prob=0},

		{name="air", prob=0},
		{name="air", prob=0},
		{name="air", prob=0},
		{name="air", prob=0},
		{name="air", prob=0},

		{name="air", prob=0},
		{name="air", prob=0},
		{name="air", prob=0},
		{name="air", prob=0},
		{name="air", prob=0},

		{name="default:leaves", prob=223},
		{name="default:tree", prob=191, force_place = true},
		{name="default:apple", prob=63},
		{name="default:tree", prob=191, force_place = true},
		{name="default:leaves", prob=223},

		{name="default:leaves", prob=223},
		{name="default:leaves", prob=255},
		{name="default:leaves", prob=255},
		{name="default:leaves", prob=255},
		{name="default:leaves", prob=223},

		{name="air", prob=0},
		{name="default:leaves", prob=223},
		{name="default:leaves", prob=223},
		{name="default:leaves", prob=223},
		{name="air", prob=0},

		-- 0

		{name="air", prob=0},
		{name="air", prob=0},
		{name="default:tree", prob=255, force_place = true},
		{name="air", prob=0},
		{name="air", prob=0},

		{name="air", prob=0},
		{name="air", prob=0},
		{name="default:tree", prob=255, force_place = true},
		{name="air", prob=0},
		{name="air", prob=0},

		{name="air", prob=0},
		{name="air", prob=0},
		{name="default:tree", prob=255, force_place = true},
		{name="air", prob=0},
		{name="air", prob=0},

		{name="air", prob=0},
		{name="air", prob=0},
		{name="default:tree", prob=255, force_place = true},
		{name="air", prob=0},
		{name="air", prob=0},

		{name="default:leaves", prob=223},
		{name="default:apple", prob=63},
		{name="default:leaves", prob=255},
		{name="default:apple", prob=63},
		{name="default:leaves", prob=223},

		{name="default:leaves", prob=223},
		{name="default:leaves", prob=255},
		{name="default:leaves", prob=255},
		{name="default:leaves", prob=255},
		{name="default:leaves", prob=223},

		{name="air", prob=0},
		{name="default:leaves", prob=223},
		{name="default:leaves", prob=255},
		{name="default:leaves", prob=223},
		{name="air", prob=0},

		-- 1

		{name="air", prob=0},
		{name="air", prob=0},
		{name="air", prob=0},
		{name="air", prob=0},
		{name="air", prob=0},

		{name="air", prob=0},
		{name="air", prob=0},
		{name="air", prob=0},
		{name="air", prob=0},
		{name="air", prob=0},

		{name="air", prob=0},
		{name="air", prob=0},
		{name="air", prob=0},
		{name="air", prob=0},
		{name="air", prob=0},

		{name="air", prob=0},
		{name="air", prob=0},
		{name="air", prob=0},
		{name="air", prob=0},
		{name="air", prob=0},

		{name="default:leaves", prob=223},
		{name="default:tree", prob=191, force_place = true},
		{name="default:apple", prob=63},
		{name="default:tree", prob=191, force_place = true},
		{name="default:leaves", prob=223},

		{name="default:leaves", prob=223},
		{name="default:leaves", prob=255},
		{name="default:leaves", prob=255},
		{name="default:leaves", prob=255},
		{name="default:leaves", prob=223},

		{name="air", prob=0},
		{name="default:leaves", prob=223},
		{name="default:leaves", prob=223},
		{name="default:leaves", prob=223},
		{name="air", prob=0},

		-- 2

		{name="air", prob=0},
		{name="air", prob=0},
		{name="air", prob=0},
		{name="air", prob=0},
		{name="air", prob=0},

		{name="air", prob=0},
		{name="air", prob=0},
		{name="air", prob=0},
		{name="air", prob=0},
		{name="air", prob=0},

		{name="air", prob=0},
		{name="air", prob=0},
		{name="air", prob=0},
		{name="air", prob=0},
		{name="air", prob=0},

		{name="air", prob=0},
		{name="air", prob=0},
		{name="air", prob=0},
		{name="air", prob=0},
		{name="air", prob=0},

		{name="default:leaves", prob=191},
		{name="default:leaves", prob=223},
		{name="default:leaves", prob=223},
		{name="default:leaves", prob=223},
		{name="default:leaves", prob=191},

		{name="default:leaves", prob=191},
		{name="default:leaves", prob=223},
		{name="default:leaves", prob=223},
		{name="default:leaves", prob=223},
		{name="default:leaves", prob=191},

		{name="air", prob=0},
		{name="air", prob=0},
		{name="air", prob=0},
		{name="air", prob=0},
		{name="air", prob=0},
	},
	yslice_prob = {
		{ypos=2, prob=127},
	},
})

-- Apple tree from sapling
mts_save("apple_tree_from_sapling", {
	size = {x=5, y=7, z=5},
	data = {-- -2

		{name="air", prob=0},
		{name="air", prob=0},
		{name="air", prob=0},
		{name="air", prob=0},
		{name="air", prob=0},

		{name="air", prob=0},
		{name="air", prob=0},
		{name="air", prob=0},
		{name="air", prob=0},
		{name="air", prob=0},

		{name="air", prob=0},
		{name="air", prob=0},
		{name="air", prob=0},
		{name="air", prob=0},
		{name="air", prob=0},

		{name="air", prob=0},
		{name="air", prob=0},
		{name="air", prob=0},
		{name="air", prob=0},
		{name="air", prob=0},

		{name="default:leaves", prob=191},
		{name="default:leaves", prob=223},
		{name="default:leaves", prob=223},
		{name="default:leaves", prob=223},
		{name="default:leaves", prob=191},

		{name="default:leaves", prob=191},
		{name="default:leaves", prob=223},
		{name="default:leaves", prob=223},
		{name="default:leaves", prob=223},
		{name="default:leaves", prob=191},

		{name="air", prob=0},
		{name="air", prob=0},
		{name="air", prob=0},
		{name="air", prob=0},
		{name="air", prob=0},

		-- -1

		{name="air", prob=0},
		{name="air", prob=0},
		{name="air", prob=0},
		{name="air", prob=0},
		{name="air", prob=0},

		{name="air", prob=0},
		{name="air", prob=0},
		{name="air", prob=0},
		{name="air", prob=0},
		{name="air", prob=0},

		{name="air", prob=0},
		{name="air", prob=0},
		{name="air", prob=0},
		{name="air", prob=0},
		{name="air", prob=0},

		{name="air", prob=0},
		{name="air", prob=0},
		{name="air", prob=0},
		{name="air", prob=0},
		{name="air", prob=0},

		{name="default:leaves", prob=223},
		{name="default:tree", prob=191},
		{name="default:apple", prob=63},
		{name="default:tree", prob=191},
		{name="default:leaves", prob=223},

		{name="default:leaves", prob=223},
		{name="default:leaves", prob=255},
		{name="default:leaves", prob=255},
		{name="default:leaves", prob=255},
		{name="default:leaves", prob=223},

		{name="air", prob=0},
		{name="default:leaves", prob=223},
		{name="default:leaves", prob=223},
		{name="default:leaves", prob=223},
		{name="air", prob=0},

		-- 0

		{name="air", prob=0},
		{name="air", prob=0},
		{name="default:tree", prob=255},
		{name="air", prob=0},
		{name="air", prob=0},

		{name="air", prob=0},
		{name="air", prob=0},
		{name="default:tree", prob=255, force_place = true},
		{name="air", prob=0},
		{name="air", prob=0},

		{name="air", prob=0},
		{name="air", prob=0},
		{name="default:tree", prob=255},
		{name="air", prob=0},
		{name="air", prob=0},

		{name="air", prob=0},
		{name="air", prob=0},
		{name="default:tree", prob=255},
		{name="air", prob=0},
		{name="air", prob=0},

		{name="default:leaves", prob=223},
		{name="default:apple", prob=63},
		{name="default:leaves", prob=255},
		{name="default:apple", prob=63},
		{name="default:leaves", prob=223},

		{name="default:leaves", prob=223},
		{name="default:leaves", prob=255},
		{name="default:leaves", prob=255},
		{name="default:leaves", prob=255},
		{name="default:leaves", prob=223},

		{name="air", prob=0},
		{name="default:leaves", prob=223},
		{name="default:leaves", prob=255},
		{name="default:leaves", prob=223},
		{name="air", prob=0},

		-- 1

		{name="air", prob=0},
		{name="air", prob=0},
		{name="air", prob=0},
		{name="air", prob=0},
		{name="air", prob=0},

		{name="air", prob=0},
		{name="air", prob=0},
		{name="air", prob=0},
		{name="air", prob=0},
		{name="air", prob=0},

		{name="air", prob=0},
		{name="air", prob=0},
		{name="air", prob=0},
		{name="air", prob=0},
		{name="air", prob=0},

		{name="air", prob=0},
		{name="air", prob=0},
		{name="air", prob=0},
		{name="air", prob=0},
		{name="air", prob=0},

		{name="default:leaves", prob=223},
		{name="default:tree", prob=191},
		{name="default:apple", prob=63},
		{name="default:tree", prob=191},
		{name="default:leaves", prob=223},

		{name="default:leaves", prob=223},
		{name="default:leaves", prob=255},
		{name="default:leaves", prob=255},
		{name="default:leaves", prob=255},
		{name="default:leaves", prob=223},

		{name="air", prob=0},
		{name="default:leaves", prob=223},
		{name="default:leaves", prob=223},
		{name="default:leaves", prob=223},
		{name="air", prob=0},

		-- 2

		{name="air", prob=0},
		{name="air", prob=0},
		{name="air", prob=0},
		{name="air", prob=0},
		{name="air", prob=0},

		{name="air", prob=0},
		{name="air", prob=0},
		{name="air", prob=0},
		{name="air", prob=0},
		{name="air", prob=0},

		{name="air", prob=0},
		{name="air", prob=0},
		{name="air", prob=0},
		{name="air", prob=0},
		{name="air", prob=0},

		{name="air", prob=0},
		{name="air", prob=0},
		{name="air", prob=0},
		{name="air", prob=0},
		{name="air", prob=0},

		{name="default:leaves", prob=191},
		{name="default:leaves", prob=223},
		{name="default:leaves", prob=223},
		{name="default:leaves", prob=223},
		{name="default:leaves", prob=191},

		{name="default:leaves", prob=191},
		{name="default:leaves", prob=223},
		{name="default:leaves", prob=223},
		{name="default:leaves", prob=223},
		{name="default:leaves", prob=191},

		{name="air", prob=0},
		{name="air", prob=0},
		{name="air", prob=0},
		{name="air", prob=0},
		{name="air", prob=0},
	},
	yslice_prob = {
		{ypos=2, prob=127},
	},
})

-- Jungle tree
mts_save("jungle_tree", {
	size = {x=5, y=17, z=5},
	data = {
		-- -2

		{name="air", prob=0},
		{name="air", prob=0},
		{name="air", prob=0},
		{name="air", prob=0},
		{name="air", prob=0},

		{name="air", prob=0},
		{name="air", prob=0},
		{name="air", prob=0},
		{name="air", prob=0},
		{name="air", prob=0},

		{name="air", prob=0},
		{name="air", prob=0},
		{name="air", prob=0},
		{name="air", prob=0},
		{name="air", prob=0},

		{name="air", prob=0},
		{name="air", prob=0},
		{name="air", prob=0},
		{name="air", prob=0},
		{name="air", prob=0},

		{name="air", prob=0},
		{name="air", prob=0},
		{name="air", prob=0},
		{name="air", prob=0},
		{name="air", prob=0},

		{name="air", prob=0},
		{name="air", prob=0},
		{name="air", prob=0},
		{name="air", prob=0},
		{name="air", prob=0},

		{name="air", prob=0},
		{name="air", prob=0},
		{name="air", prob=0},
		{name="air", prob=0},
		{name="air", prob=0},

		{name="air", prob=0},
		{name="air", prob=0},
		{name="air", prob=0},
		{name="air", prob=0},
		{name="air", prob=0},

		{name="air", prob=0},
		{name="air", prob=0},
		{name="air", prob=0},
		{name="air", prob=0},
		{name="air", prob=0},

		{name="air", prob=0},
		{name="air", prob=0},
		{name="air", prob=0},
		{name="air", prob=0},
		{name="air", prob=0},

		{name="default:jungleleaves", prob=223},
		{name="default:jungleleaves", prob=255},
		{name="default:jungleleaves", prob=223},
		{name="air", prob=0},
		{name="air", prob=0},

		{name="air", prob=0},
		{name="air", prob=0},
		{name="default:jungleleaves", prob=223},
		{name="default:jungleleaves", prob=255},
		{name="default:jungleleaves", prob=223},

		{name="air", prob=0},
		{name="air", prob=0},
		{name="air", prob=0},
		{name="air", prob=0},
		{name="air", prob=0},

		{name="air", prob=0},
		{name="air", prob=0},
		{name="air", prob=0},
		{name="air", prob=0},
		{name="air", prob=0},

		{name="default:jungleleaves", prob=191},
		{name="default:jungleleaves", prob=223},
		{name="default:jungleleaves", prob=223},
		{name="default:jungleleaves", prob=223},
		{name="default:jungleleaves", prob=191},

		{name="default:jungleleaves", prob=191},
		{name="default:jungleleaves", prob=223},
		{name="default:jungleleaves", prob=223},
		{name="default:jungleleaves", prob=223},
		{name="default:jungleleaves", prob=191},

		{name="air", prob=0},
		{name="air", prob=0},
		{name="air", prob=0},
		{name="air", prob=0},
		{name="air", prob=0},

		-- -1

		{name="air", prob=0},
		{name="air", prob=0},
		{name="default:jungletree", prob=255, force_place = true},
		{name="air", prob=0},
		{name="air", prob=0},

		{name="air", prob=0},
		{name="air", prob=0},
		{name="default:jungletree", prob=255, force_place = true},
		{name="air", prob=0},
		{name="air", prob=0},

		{name="air", prob=0},
		{name="air", prob=0},
		{name="default:jungletree", prob=127, force_place = true},
		{name="air", prob=0},
		{name="air", prob=0},

		{name="air", prob=0},
		{name="air", prob=0},
		{name="air", prob=0},
		{name="air", prob=0},
		{name="air", prob=0},

		{name="air", prob=0},
		{name="air", prob=0},
		{name="air", prob=0},
		{name="air", prob=0},
		{name="air", prob=0},

		{name="air", prob=0},
		{name="air", prob=0},
		{name="air", prob=0},
		{name="air", prob=0},
		{name="air", prob=0},

		{name="air", prob=0},
		{name="air", prob=0},
		{name="air", prob=0},
		{name="air", prob=0},
		{name="air", prob=0},

		{name="air", prob=0},
		{name="air", prob=0},
		{name="air", prob=0},
		{name="air", prob=0},
		{name="air", prob=0},

		{name="air", prob=0},
		{name="air", prob=0},
		{name="air", prob=0},
		{name="air", prob=0},
		{name="air", prob=0},

		{name="air", prob=0},
		{name="air", prob=0},
		{name="air", prob=0},
		{name="air", prob=0},
		{name="air", prob=0},

		{name="default:jungleleaves", prob=255},
		{name="default:jungletree", prob=255, force_place = true},
		{name="default:jungleleaves", prob=255},
		{name="air", prob=0},
		{name="air", prob=0},

		{name="air", prob=0},
		{name="air", prob=0},
		{name="default:jungleleaves", prob=255},
		{name="default:jungletree", prob=255, force_place = true},
		{name="default:jungleleaves", prob=255},

		{name="air", prob=0},
		{name="air", prob=0},
		{name="air", prob=0},
		{name="air", prob=0},
		{name="air", prob=0},

		{name="air", prob=0},
		{name="air", prob=0},
		{name="air", prob=0},
		{name="air", prob=0},
		{name="air", prob=0},

		{name="default:jungleleaves", prob=223},
		{name="default:jungletree", prob=191, force_place = true},
		{name="default:jungleleaves", prob=255},
		{name="default:jungletree", prob=191, force_place = true},
		{name="default:jungleleaves", prob=223},

		{name="default:jungleleaves", prob=223},
		{name="default:jungleleaves", prob=255},
		{name="default:jungleleaves", prob=255},
		{name="default:jungleleaves", prob=255},
		{name="default:jungleleaves", prob=223},

		{name="air", prob=0},
		{name="default:jungleleaves", prob=223},
		{name="default:jungleleaves", prob=223},
		{name="default:jungleleaves", prob=223},
		{name="air", prob=0},

		-- 0

		{name="air", prob=0},
		{name="default:jungletree", prob=255, force_place = true},
		{name="default:jungletree", prob=255, force_place = true},
		{name="default:jungletree", prob=255, force_place = true},
		{name="air", prob=0},

		{name="air", prob=0},
		{name="default:jungletree", prob=255},
		{name="default:jungletree", prob=255, force_place = true},
		{name="default:jungletree", prob=255},
		{name="air", prob=0},

		{name="air", prob=0},
		{name="default:jungletree", prob=127, force_place = true},
		{name="default:jungletree", prob=255, force_place = true},
		{name="default:jungletree", prob=127, force_place = true},
		{name="air", prob=0},

		{name="air", prob=0},
		{name="air", prob=0},
		{name="default:jungletree", prob=255, force_place = true},
		{name="air", prob=0},
		{name="air", prob=0},

		{name="air", prob=0},
		{name="air", prob=0},
		{name="default:jungletree", prob=255, force_place = true},
		{name="air", prob=0},
		{name="air", prob=0},

		{name="air", prob=0},
		{name="air", prob=0},
		{name="default:jungletree", prob=255, force_place = true},
		{name="air", prob=0},
		{name="air", prob=0},

		{name="air", prob=0},
		{name="air", prob=0},
		{name="default:jungletree", prob=255, force_place = true},
		{name="air", prob=0},
		{name="air", prob=0},

		{name="air", prob=0},
		{name="air", prob=0},
		{name="default:jungletree", prob=255, force_place = true},
		{name="air", prob=0},
		{name="air", prob=0},

		{name="air", prob=0},
		{name="air", prob=0},
		{name="default:jungletree", prob=255, force_place = true},
		{name="default:jungleleaves", prob=255},
		{name="default:jungleleaves", prob=223},

		{name="default:jungleleaves", prob=223},
		{name="default:jungleleaves", prob=255},
		{name="default:jungletree", prob=255, force_place = true},
		{name="air", prob=0},
		{name="air", prob=0},

		{name="default:jungleleaves", prob=223},
		{name="default:jungleleaves", prob=255},
		{name="default:jungletree", prob=255, force_place = true},
		{name="air", prob=0},
		{name="air", prob=0},

		{name="air", prob=0},
		{name="air", prob=0},
		{name="default:jungletree", prob=255, force_place = true},
		{name="default:jungleleaves", prob=255},
		{name="default:jungleleaves", prob=223},

		{name="air", prob=0},
		{name="air", prob=0},
		{name="default:jungletree", prob=255, force_place = true},
		{name="air", prob=0},
		{name="air", prob=0},

		{name="air", prob=0},
		{name="air", prob=0},
		{name="default:jungletree", prob=255, force_place = true},
		{name="air", prob=0},
		{name="air", prob=0},

		{name="default:jungleleaves", prob=223},
		{name="default:jungleleaves", prob=255},
		{name="default:jungleleaves", prob=255},
		{name="default:jungleleaves", prob=255},
		{name="default:jungleleaves", prob=223},

		{name="default:jungleleaves", prob=223},
		{name="default:jungleleaves", prob=255},
		{name="default:jungleleaves", prob=255},
		{name="default:jungleleaves", prob=255},
		{name="default:jungleleaves", prob=223},

		{name="air", prob=0},
		{name="default:jungleleaves", prob=223},
		{name="default:jungleleaves", prob=255},
		{name="default:jungleleaves", prob=223},
		{name="air", prob=0},

		-- 1

		{name="air", prob=0},
		{name="air", prob=0},
		{name="default:jungletree", prob=255, force_place = true},
		{name="air", prob=0},
		{name="air", prob=0},

		{name="air", prob=0},
		{name="air", prob=0},
		{name="default:jungletree", prob=255, force_place = true},
		{name="air", prob=0},
		{name="air", prob=0},

		{name="air", prob=0},
		{name="air", prob=0},
		{name="default:jungletree", prob=127, force_place = true},
		{name="air", prob=0},
		{name="air", prob=0},

		{name="air", prob=0},
		{name="air", prob=0},
		{name="air", prob=0},
		{name="air", prob=0},
		{name="air", prob=0},

		{name="air", prob=0},
		{name="air", prob=0},
		{name="air", prob=0},
		{name="air", prob=0},
		{name="air", prob=0},

		{name="air", prob=0},
		{name="air", prob=0},
		{name="air", prob=0},
		{name="air", prob=0},
		{name="air", prob=0},

		{name="air", prob=0},
		{name="air", prob=0},
		{name="air", prob=0},
		{name="air", prob=0},
		{name="air", prob=0},

		{name="air", prob=0},
		{name="air", prob=0},
		{name="air", prob=0},
		{name="air", prob=0},
		{name="air", prob=0},

		{name="air", prob=0},
		{name="air", prob=0},
		{name="default:jungleleaves", prob=255},
		{name="default:jungletree", prob=255, force_place = true},
		{name="default:jungleleaves", prob=255},

		{name="default:jungleleaves", prob=255},
		{name="default:jungletree", prob=255, force_place = true},
		{name="default:jungleleaves", prob=255},
		{name="air", prob=0},
		{name="air", prob=0},

		{name="air", prob=0},
		{name="air", prob=0},
		{name="air", prob=0},
		{name="air", prob=0},
		{name="air", prob=0},

		{name="air", prob=0},
		{name="air", prob=0},
		{name="air", prob=0},
		{name="air", prob=0},
		{name="air", prob=0},

		{name="air", prob=0},
		{name="air", prob=0},
		{name="air", prob=0},
		{name="air", prob=0},
		{name="air", prob=0},

		{name="air", prob=0},
		{name="air", prob=0},
		{name="air", prob=0},
		{name="air", prob=0},
		{name="air", prob=0},

		{name="default:jungleleaves", prob=223},
		{name="default:jungletree", prob=191, force_place = true},
		{name="default:jungleleaves", prob=255},
		{name="default:jungletree", prob=191, force_place = true},
		{name="default:jungleleaves", prob=223},

		{name="default:jungleleaves", prob=223},
		{name="default:jungleleaves", prob=255},
		{name="default:jungleleaves", prob=255},
		{name="default:jungleleaves", prob=255},
		{name="default:jungleleaves", prob=223},

		{name="air", prob=0},
		{name="default:jungleleaves", prob=223},
		{name="default:jungleleaves", prob=223},
		{name="default:jungleleaves", prob=223},
		{name="air", prob=0},

		-- 2

		{name="air", prob=0},
		{name="air", prob=0},
		{name="air", prob=0},
		{name="air", prob=0},
		{name="air", prob=0},

		{name="air", prob=0},
		{name="air", prob=0},
		{name="air", prob=0},
		{name="air", prob=0},
		{name="air", prob=0},

		{name="air", prob=0},
		{name="air", prob=0},
		{name="air", prob=0},
		{name="air", prob=0},
		{name="air", prob=0},

		{name="air", prob=0},
		{name="air", prob=0},
		{name="air", prob=0},
		{name="air", prob=0},
		{name="air", prob=0},

		{name="air", prob=0},
		{name="air", prob=0},
		{name="air", prob=0},
		{name="air", prob=0},
		{name="air", prob=0},

		{name="air", prob=0},
		{name="air", prob=0},
		{name="air", prob=0},
		{name="air", prob=0},
		{name="air", prob=0},

		{name="air", prob=0},
		{name="air", prob=0},
		{name="air", prob=0},
		{name="air", prob=0},
		{name="air", prob=0},

		{name="air", prob=0},
		{name="air", prob=0},
		{name="air", prob=0},
		{name="air", prob=0},
		{name="air", prob=0},

		{name="air", prob=0},
		{name="air", prob=0},
		{name="default:jungleleaves", prob=223},
		{name="default:jungleleaves", prob=255},
		{name="default:jungleleaves", prob=223},

		{name="default:jungleleaves", prob=223},
		{name="default:jungleleaves", prob=255},
		{name="default:jungleleaves", prob=223},
		{name="air", prob=0},
		{name="air", prob=0},

		{name="air", prob=0},
		{name="air", prob=0},
		{name="air", prob=0},
		{name="air", prob=0},
		{name="air", prob=0},

		{name="air", prob=0},
		{name="air", prob=0},
		{name="air", prob=0},
		{name="air", prob=0},
		{name="air", prob=0},

		{name="air", prob=0},
		{name="air", prob=0},
		{name="air", prob=0},
		{name="air", prob=0},
		{name="air", prob=0},

		{name="air", prob=0},
		{name="air", prob=0},
		{name="air", prob=0},
		{name="air", prob=0},
		{name="air", prob=0},

		{name="default:jungleleaves", prob=191},
		{name="default:jungleleaves", prob=223},
		{name="default:jungleleaves", prob=223},
		{name="default:jungleleaves", prob=223},
		{name="default:jungleleaves", prob=191},

		{name="default:jungleleaves", prob=191},
		{name="default:jungleleaves", prob=223},
		{name="default:jungleleaves", prob=223},
		{name="default:jungleleaves", prob=223},
		{name="default:jungleleaves", prob=191},

		{name="air", prob=0},
		{name="air", prob=0},
		{name="air", prob=0},
		{name="air", prob=0},
		{name="air", prob=0},
	},
	yslice_prob = {
		{ypos=8, prob=127},
		{ypos=9, prob=127},
		{ypos=10, prob=127},
		{ypos=11, prob=127},
	},
})

-- Jungle tree from sapling
mts_save("jungle_tree_from_sapling", {
	size = {x=5, y=17, z=5},
	data = {
		-- -2

		{name="air", prob=0},
		{name="air", prob=0},
		{name="air", prob=0},
		{name="air", prob=0},
		{name="air", prob=0},

		{name="air", prob=0},
		{name="air", prob=0},
		{name="air", prob=0},
		{name="air", prob=0},
		{name="air", prob=0},

		{name="air", prob=0},
		{name="air", prob=0},
		{name="air", prob=0},
		{name="air", prob=0},
		{name="air", prob=0},

		{name="air", prob=0},
		{name="air", prob=0},
		{name="air", prob=0},
		{name="air", prob=0},
		{name="air", prob=0},

		{name="air", prob=0},
		{name="air", prob=0},
		{name="air", prob=0},
		{name="air", prob=0},
		{name="air", prob=0},

		{name="air", prob=0},
		{name="air", prob=0},
		{name="air", prob=0},
		{name="air", prob=0},
		{name="air", prob=0},

		{name="air", prob=0},
		{name="air", prob=0},
		{name="air", prob=0},
		{name="air", prob=0},
		{name="air", prob=0},

		{name="air", prob=0},
		{name="air", prob=0},
		{name="air", prob=0},
		{name="air", prob=0},
		{name="air", prob=0},

		{name="air", prob=0},
		{name="air", prob=0},
		{name="air", prob=0},
		{name="air", prob=0},
		{name="air", prob=0},

		{name="air", prob=0},
		{name="air", prob=0},
		{name="air", prob=0},
		{name="air", prob=0},
		{name="air", prob=0},

		{name="default:jungleleaves", prob=223},
		{name="default:jungleleaves", prob=255},
		{name="default:jungleleaves", prob=223},
		{name="air", prob=0},
		{name="air", prob=0},

		{name="air", prob=0},
		{name="air", prob=0},
		{name="default:jungleleaves", prob=223},
		{name="default:jungleleaves", prob=255},
		{name="default:jungleleaves", prob=223},

		{name="air", prob=0},
		{name="air", prob=0},
		{name="air", prob=0},
		{name="air", prob=0},
		{name="air", prob=0},

		{name="air", prob=0},
		{name="air", prob=0},
		{name="air", prob=0},
		{name="air", prob=0},
		{name="air", prob=0},

		{name="default:jungleleaves", prob=191},
		{name="default:jungleleaves", prob=223},
		{name="default:jungleleaves", prob=223},
		{name="default:jungleleaves", prob=223},
		{name="default:jungleleaves", prob=191},

		{name="default:jungleleaves", prob=191},
		{name="default:jungleleaves", prob=223},
		{name="default:jungleleaves", prob=223},
		{name="default:jungleleaves", prob=223},
		{name="default:jungleleaves", prob=191},

		{name="air", prob=0},
		{name="air", prob=0},
		{name="air", prob=0},
		{name="air", prob=0},
		{name="air", prob=0},

		-- -1

		{name="air", prob=0},
		{name="air", prob=0},
		{name="default:jungletree", prob=255},
		{name="air", prob=0},
		{name="air", prob=0},

		{name="air", prob=0},
		{name="air", prob=0},
		{name="default:jungletree", prob=255},
		{name="air", prob=0},
		{name="air", prob=0},

		{name="air", prob=0},
		{name="air", prob=0},
		{name="default:jungletree", prob=127},
		{name="air", prob=0},
		{name="air", prob=0},

		{name="air", prob=0},
		{name="air", prob=0},
		{name="air", prob=0},
		{name="air", prob=0},
		{name="air", prob=0},

		{name="air", prob=0},
		{name="air", prob=0},
		{name="air", prob=0},
		{name="air", prob=0},
		{name="air", prob=0},

		{name="air", prob=0},
		{name="air", prob=0},
		{name="air", prob=0},
		{name="air", prob=0},
		{name="air", prob=0},

		{name="air", prob=0},
		{name="air", prob=0},
		{name="air", prob=0},
		{name="air", prob=0},
		{name="air", prob=0},

		{name="air", prob=0},
		{name="air", prob=0},
		{name="air", prob=0},
		{name="air", prob=0},
		{name="air", prob=0},

		{name="air", prob=0},
		{name="air", prob=0},
		{name="air", prob=0},
		{name="air", prob=0},
		{name="air", prob=0},

		{name="air", prob=0},
		{name="air", prob=0},
		{name="air", prob=0},
		{name="air", prob=0},
		{name="air", prob=0},

		{name="default:jungleleaves", prob=255},
		{name="default:jungletree", prob=255},
		{name="default:jungleleaves", prob=255},
		{name="air", prob=0},
		{name="air", prob=0},

		{name="air", prob=0},
		{name="air", prob=0},
		{name="default:jungleleaves", prob=255},
		{name="default:jungletree", prob=255},
		{name="default:jungleleaves", prob=255},

		{name="air", prob=0},
		{name="air", prob=0},
		{name="air", prob=0},
		{name="air", prob=0},
		{name="air", prob=0},

		{name="air", prob=0},
		{name="air", prob=0},
		{name="air", prob=0},
		{name="air", prob=0},
		{name="air", prob=0},

		{name="default:jungleleaves", prob=223},
		{name="default:jungletree", prob=191},
		{name="default:jungleleaves", prob=255},
		{name="default:jungletree", prob=191},
		{name="default:jungleleaves", prob=223},

		{name="default:jungleleaves", prob=223},
		{name="default:jungleleaves", prob=255},
		{name="default:jungleleaves", prob=255},
		{name="default:jungleleaves", prob=255},
		{name="default:jungleleaves", prob=223},

		{name="air", prob=0},
		{name="default:jungleleaves", prob=223},
		{name="default:jungleleaves", prob=223},
		{name="default:jungleleaves", prob=223},
		{name="air", prob=0},

		-- 0

		{name="air", prob=0},
		{name="default:jungletree", prob=255},
		{name="default:jungletree", prob=255},
		{name="default:jungletree", prob=255},
		{name="air", prob=0},

		{name="air", prob=0},
		{name="default:jungletree", prob=255},
		{name="default:jungletree", prob=255, force_place = true},
		{name="default:jungletree", prob=255},
		{name="air", prob=0},

		{name="air", prob=0},
		{name="default:jungletree", prob=127},
		{name="default:jungletree", prob=255},
		{name="default:jungletree", prob=127},
		{name="air", prob=0},

		{name="air", prob=0},
		{name="air", prob=0},
		{name="default:jungletree", prob=255},
		{name="air", prob=0},
		{name="air", prob=0},

		{name="air", prob=0},
		{name="air", prob=0},
		{name="default:jungletree", prob=255},
		{name="air", prob=0},
		{name="air", prob=0},

		{name="air", prob=0},
		{name="air", prob=0},
		{name="default:jungletree", prob=255},
		{name="air", prob=0},
		{name="air", prob=0},

		{name="air", prob=0},
		{name="air", prob=0},
		{name="default:jungletree", prob=255},
		{name="air", prob=0},
		{name="air", prob=0},

		{name="air", prob=0},
		{name="air", prob=0},
		{name="default:jungletree", prob=255},
		{name="air", prob=0},
		{name="air", prob=0},

		{name="air", prob=0},
		{name="air", prob=0},
		{name="default:jungletree", prob=255},
		{name="default:jungleleaves", prob=255},
		{name="default:jungleleaves", prob=223},

		{name="default:jungleleaves", prob=223},
		{name="default:jungleleaves", prob=255},
		{name="default:jungletree", prob=255},
		{name="air", prob=0},
		{name="air", prob=0},

		{name="default:jungleleaves", prob=223},
		{name="default:jungleleaves", prob=255},
		{name="default:jungletree", prob=255},
		{name="air", prob=0},
		{name="air", prob=0},

		{name="air", prob=0},
		{name="air", prob=0},
		{name="default:jungletree", prob=255},
		{name="default:jungleleaves", prob=255},
		{name="default:jungleleaves", prob=223},

		{name="air", prob=0},
		{name="air", prob=0},
		{name="default:jungletree", prob=255},
		{name="air", prob=0},
		{name="air", prob=0},

		{name="air", prob=0},
		{name="air", prob=0},
		{name="default:jungletree", prob=255},
		{name="air", prob=0},
		{name="air", prob=0},

		{name="default:jungleleaves", prob=223},
		{name="default:jungleleaves", prob=255},
		{name="default:jungleleaves", prob=255},
		{name="default:jungleleaves", prob=255},
		{name="default:jungleleaves", prob=223},

		{name="default:jungleleaves", prob=223},
		{name="default:jungleleaves", prob=255},
		{name="default:jungleleaves", prob=255},
		{name="default:jungleleaves", prob=255},
		{name="default:jungleleaves", prob=223},

		{name="air", prob=0},
		{name="default:jungleleaves", prob=223},
		{name="default:jungleleaves", prob=255},
		{name="default:jungleleaves", prob=223},
		{name="air", prob=0},

		-- 1

		{name="air", prob=0},
		{name="air", prob=0},
		{name="default:jungletree", prob=255},
		{name="air", prob=0},
		{name="air", prob=0},

		{name="air", prob=0},
		{name="air", prob=0},
		{name="default:jungletree", prob=255},
		{name="air", prob=0},
		{name="air", prob=0},

		{name="air", prob=0},
		{name="air", prob=0},
		{name="default:jungletree", prob=127},
		{name="air", prob=0},
		{name="air", prob=0},

		{name="air", prob=0},
		{name="air", prob=0},
		{name="air", prob=0},
		{name="air", prob=0},
		{name="air", prob=0},

		{name="air", prob=0},
		{name="air", prob=0},
		{name="air", prob=0},
		{name="air", prob=0},
		{name="air", prob=0},

		{name="air", prob=0},
		{name="air", prob=0},
		{name="air", prob=0},
		{name="air", prob=0},
		{name="air", prob=0},

		{name="air", prob=0},
		{name="air", prob=0},
		{name="air", prob=0},
		{name="air", prob=0},
		{name="air", prob=0},

		{name="air", prob=0},
		{name="air", prob=0},
		{name="air", prob=0},
		{name="air", prob=0},
		{name="air", prob=0},

		{name="air", prob=0},
		{name="air", prob=0},
		{name="default:jungleleaves", prob=255},
		{name="default:jungletree", prob=255},
		{name="default:jungleleaves", prob=255},

		{name="default:jungleleaves", prob=255},
		{name="default:jungletree", prob=255},
		{name="default:jungleleaves", prob=255},
		{name="air", prob=0},
		{name="air", prob=0},

		{name="air", prob=0},
		{name="air", prob=0},
		{name="air", prob=0},
		{name="air", prob=0},
		{name="air", prob=0},

		{name="air", prob=0},
		{name="air", prob=0},
		{name="air", prob=0},
		{name="air", prob=0},
		{name="air", prob=0},

		{name="air", prob=0},
		{name="air", prob=0},
		{name="air", prob=0},
		{name="air", prob=0},
		{name="air", prob=0},

		{name="air", prob=0},
		{name="air", prob=0},
		{name="air", prob=0},
		{name="air", prob=0},
		{name="air", prob=0},

		{name="default:jungleleaves", prob=223},
		{name="default:jungletree", prob=191},
		{name="default:jungleleaves", prob=255},
		{name="default:jungletree", prob=191},
		{name="default:jungleleaves", prob=223},

		{name="default:jungleleaves", prob=223},
		{name="default:jungleleaves", prob=255},
		{name="default:jungleleaves", prob=255},
		{name="default:jungleleaves", prob=255},
		{name="default:jungleleaves", prob=223},

		{name="air", prob=0},
		{name="default:jungleleaves", prob=223},
		{name="default:jungleleaves", prob=223},
		{name="default:jungleleaves", prob=223},
		{name="air", prob=0},

		-- 2

		{name="air", prob=0},
		{name="air", prob=0},
		{name="air", prob=0},
		{name="air", prob=0},
		{name="air", prob=0},

		{name="air", prob=0},
		{name="air", prob=0},
		{name="air", prob=0},
		{name="air", prob=0},
		{name="air", prob=0},

		{name="air", prob=0},
		{name="air", prob=0},
		{name="air", prob=0},
		{name="air", prob=0},
		{name="air", prob=0},

		{name="air", prob=0},
		{name="air", prob=0},
		{name="air", prob=0},
		{name="air", prob=0},
		{name="air", prob=0},

		{name="air", prob=0},
		{name="air", prob=0},
		{name="air", prob=0},
		{name="air", prob=0},
		{name="air", prob=0},

		{name="air", prob=0},
		{name="air", prob=0},
		{name="air", prob=0},
		{name="air", prob=0},
		{name="air", prob=0},

		{name="air", prob=0},
		{name="air", prob=0},
		{name="air", prob=0},
		{name="air", prob=0},
		{name="air", prob=0},

		{name="air", prob=0},
		{name="air", prob=0},
		{name="air", prob=0},
		{name="air", prob=0},
		{name="air", prob=0},

		{name="air", prob=0},
		{name="air", prob=0},
		{name="default:jungleleaves", prob=223},
		{name="default:jungleleaves", prob=255},
		{name="default:jungleleaves", prob=223},

		{name="default:jungleleaves", prob=223},
		{name="default:jungleleaves", prob=255},
		{name="default:jungleleaves", prob=223},
		{name="air", prob=0},
		{name="air", prob=0},

		{name="air", prob=0},
		{name="air", prob=0},
		{name="air", prob=0},
		{name="air", prob=0},
		{name="air", prob=0},

		{name="air", prob=0},
		{name="air", prob=0},
		{name="air", prob=0},
		{name="air", prob=0},
		{name="air", prob=0},

		{name="air", prob=0},
		{name="air", prob=0},
		{name="air", prob=0},
		{name="air", prob=0},
		{name="air", prob=0},

		{name="air", prob=0},
		{name="air", prob=0},
		{name="air", prob=0},
		{name="air", prob=0},
		{name="air", prob=0},

		{name="default:jungleleaves", prob=191},
		{name="default:jungleleaves", prob=223},
		{name="default:jungleleaves", prob=223},
		{name="default:jungleleaves", prob=223},
		{name="default:jungleleaves", prob=191},

		{name="default:jungleleaves", prob=191},
		{name="default:jungleleaves", prob=223},
		{name="default:jungleleaves", prob=223},
		{name="default:jungleleaves", prob=223},
		{name="default:jungleleaves", prob=191},

		{name="air", prob=0},
		{name="air", prob=0},
		{name="air", prob=0},
		{name="air", prob=0},
		{name="air", prob=0},
	},
	yslice_prob = {
		{ypos=8, prob=127},
		{ypos=9, prob=127},
		{ypos=10, prob=127},
		{ypos=11, prob=127},
	},
})

-- Pine tree
mts_save("pine_tree", {
	size = {x=5, y=14, z=5},
	data = {-- -2

		{name="air", prob=0},
		{name="air", prob=0},
		{name="air", prob=0},
		{name="air", prob=0},
		{name="air", prob=0},

		{name="air", prob=0},
		{name="air", prob=0},
		{name="air", prob=0},
		{name="air", prob=0},
		{name="air", prob=0},

		{name="air", prob=0},
		{name="air", prob=0},
		{name="air", prob=0},
		{name="air", prob=0},
		{name="air", prob=0},

		{name="air", prob=0},
		{name="air", prob=0},
		{name="air", prob=0},
		{name="air", prob=0},
		{name="air", prob=0},

		{name="air", prob=0},
		{name="air", prob=0},
		{name="air", prob=0},
		{name="air", prob=0},
		{name="air", prob=0},

		{name="default:pine_needles", prob=191},
		{name="default:pine_needles", prob=223},
		{name="default:pine_needles", prob=255},
		{name="default:pine_needles", prob=223},
		{name="default:pine_needles", prob=191},

		{name="air", prob=0},
		{name="air", prob=0},
		{name="air", prob=0},
		{name="air", prob=0},
		{name="air", prob=0},

		{name="air", prob=0},
		{name="air", prob=0},
		{name="air", prob=0},
		{name="air", prob=0},
		{name="air", prob=0},

		{name="default:pine_needles", prob=191},
		{name="default:pine_needles", prob=223},
		{name="default:pine_needles", prob=255},
		{name="default:pine_needles", prob=223},
		{name="default:pine_needles", prob=191},

		{name="air", prob=0},
		{name="air", prob=0},
		{name="air", prob=0},
		{name="air", prob=0},
		{name="air", prob=0},

		{name="air", prob=0},
		{name="air", prob=0},
		{name="air", prob=0},
		{name="air", prob=0},
		{name="air", prob=0},

		{name="default:pine_needles", prob=191},
		{name="default:pine_needles", prob=223},
		{name="default:pine_needles", prob=255},
		{name="default:pine_needles", prob=223},
		{name="default:pine_needles", prob=191},

		{name="air", prob=0},
		{name="air", prob=0},
		{name="air", prob=0},
		{name="air", prob=0},
		{name="air", prob=0},

		{name="air", prob=0},
		{name="air", prob=0},
		{name="air", prob=0},
		{name="air", prob=0},
		{name="air", prob=0},

		-- -1

		{name="air", prob=0},
		{name="air", prob=0},
		{name="air", prob=0},
		{name="air", prob=0},
		{name="air", prob=0},

		{name="air", prob=0},
		{name="air", prob=0},
		{name="air", prob=0},
		{name="air", prob=0},
		{name="air", prob=0},

		{name="air", prob=0},
		{name="air", prob=0},
		{name="air", prob=0},
		{name="air", prob=0},
		{name="air", prob=0},

		{name="air", prob=0},
		{name="air", prob=0},
		{name="air", prob=0},
		{name="air", prob=0},
		{name="air", prob=0},

		{name="air", prob=0},
		{name="air", prob=0},
		{name="air", prob=0},
		{name="air", prob=0},
		{name="air", prob=0},

		{name="default:pine_needles", prob=223},
		{name="default:pine_needles", prob=255},
		{name="air", prob=0},
		{name="default:pine_needles", prob=255},
		{name="default:pine_needles", prob=223},

		{name="air", prob=0},
		{name="default:pine_needles", prob=255},
		{name="default:pine_needles", prob=255},
		{name="default:pine_needles", prob=255},
		{name="air", prob=0},

		{name="air", prob=0},
		{name="air", prob=0},
		{name="air", prob=0},
		{name="air", prob=0},
		{name="air", prob=0},

		{name="default:pine_needles", prob=223},
		{name="default:pine_needles", prob=255},
		{name="air", prob=0},
		{name="default:pine_needles", prob=255},
		{name="default:pine_needles", prob=223},

		{name="air", prob=0},
		{name="default:pine_needles", prob=255},
		{name="default:pine_needles", prob=255},
		{name="default:pine_needles", prob=255},
		{name="air", prob=0},

		{name="air", prob=0},
		{name="air", prob=0},
		{name="air", prob=0},
		{name="air", prob=0},
		{name="air", prob=0},

		{name="default:pine_needles", prob=223},
		{name="default:pine_needles", prob=255},
		{name="air", prob=0},
		{name="default:pine_needles", prob=255},
		{name="default:pine_needles", prob=223},

		{name="air", prob=0},
		{name="default:pine_needles", prob=255},
		{name="default:pine_needles", prob=255},
		{name="default:pine_needles", prob=255},
		{name="air", prob=0},

		{name="air", prob=0},
		{name="air", prob=0},
		{name="air", prob=0},
		{name="air", prob=0},
		{name="air", prob=0},

		-- 0

		{name="air", prob=0},
		{name="air", prob=0},
		{name="default:pine_tree", prob=255, force_place = true},
		{name="air", prob=0},
		{name="air", prob=0},

		{name="air", prob=0},
		{name="air", prob=0},
		{name="default:pine_tree", prob=255, force_place = true},
		{name="air", prob=0},
		{name="air", prob=0},

		{name="air", prob=0},
		{name="air", prob=0},
		{name="default:pine_tree", prob=255, force_place = true},
		{name="air", prob=0},
		{name="air", prob=0},

		{name="air", prob=0},
		{name="air", prob=0},
		{name="default:pine_tree", prob=255, force_place = true},
		{name="air", prob=0},
		{name="air", prob=0},

		{name="air", prob=0},
		{name="air", prob=0},
		{name="default:pine_tree", prob=255, force_place = true},
		{name="air", prob=0},
		{name="air", prob=0},

		{name="default:pine_needles", prob=255},
		{name="air", prob=0},
		{name="default:pine_tree", prob=255, force_place = true},
		{name="air", prob=0},
		{name="default:pine_needles", prob=255},

		{name="air", prob=0},
		{name="default:pine_needles", prob=255},
		{name="default:pine_tree", prob=255, force_place = true},
		{name="default:pine_needles", prob=255},
		{name="air", prob=0},

		{name="air", prob=0},
		{name="air", prob=0},
		{name="default:pine_tree", prob=255, force_place = true},
		{name="air", prob=0},
		{name="air", prob=0},

		{name="default:pine_needles", prob=255},
		{name="air", prob=0},
		{name="default:pine_tree", prob=255, force_place = true},
		{name="air", prob=0},
		{name="default:pine_needles", prob=255},

		{name="air", prob=0},
		{name="default:pine_needles", prob=255},
		{name="default:pine_tree", prob=255, force_place = true},
		{name="default:pine_needles", prob=255},
		{name="air", prob=0},

		{name="air", prob=0},
		{name="air", prob=0},
		{name="default:pine_tree", prob=255, force_place = true},
		{name="air", prob=0},
		{name="air", prob=0},

		{name="default:pine_needles", prob=255},
		{name="air", prob=0},
		{name="default:pine_tree", prob=255, force_place = true},
		{name="air", prob=0},
		{name="default:pine_needles", prob=255},

		{name="air", prob=0},
		{name="default:pine_needles", prob=255},
		{name="default:pine_needles", prob=255},
		{name="default:pine_needles", prob=255},
		{name="air", prob=0},

		{name="air", prob=0},
		{name="air", prob=0},
		{name="default:pine_needles", prob=255},
		{name="air", prob=0},
		{name="air", prob=0},

		-- 1

		{name="air", prob=0},
		{name="air", prob=0},
		{name="air", prob=0},
		{name="air", prob=0},
		{name="air", prob=0},

		{name="air", prob=0},
		{name="air", prob=0},
		{name="air", prob=0},
		{name="air", prob=0},
		{name="air", prob=0},

		{name="air", prob=0},
		{name="air", prob=0},
		{name="air", prob=0},
		{name="air", prob=0},
		{name="air", prob=0},

		{name="air", prob=0},
		{name="air", prob=0},
		{name="air", prob=0},
		{name="air", prob=0},
		{name="air", prob=0},

		{name="air", prob=0},
		{name="air", prob=0},
		{name="air", prob=0},
		{name="air", prob=0},
		{name="air", prob=0},

		{name="default:pine_needles", prob=223},
		{name="default:pine_needles", prob=255},
		{name="air", prob=0},
		{name="default:pine_needles", prob=255},
		{name="default:pine_needles", prob=223},

		{name="air", prob=0},
		{name="default:pine_needles", prob=255},
		{name="default:pine_needles", prob=255},
		{name="default:pine_needles", prob=255},
		{name="air", prob=0},

		{name="air", prob=0},
		{name="air", prob=0},
		{name="air", prob=0},
		{name="air", prob=0},
		{name="air", prob=0},

		{name="default:pine_needles", prob=223},
		{name="default:pine_needles", prob=255},
		{name="air", prob=0},
		{name="default:pine_needles", prob=255},
		{name="default:pine_needles", prob=223},

		{name="air", prob=0},
		{name="default:pine_needles", prob=255},
		{name="default:pine_needles", prob=255},
		{name="default:pine_needles", prob=255},
		{name="air", prob=0},

		{name="air", prob=0},
		{name="air", prob=0},
		{name="air", prob=0},
		{name="air", prob=0},
		{name="air", prob=0},

		{name="default:pine_needles", prob=223},
		{name="default:pine_needles", prob=255},
		{name="air", prob=0},
		{name="default:pine_needles", prob=255},
		{name="default:pine_needles", prob=223},

		{name="air", prob=0},
		{name="default:pine_needles", prob=255},
		{name="default:pine_needles", prob=255},
		{name="default:pine_needles", prob=255},
		{name="air", prob=0},

		{name="air", prob=0},
		{name="air", prob=0},
		{name="air", prob=0},
		{name="air", prob=0},
		{name="air", prob=0},

		-- 2

		{name="air", prob=0},
		{name="air", prob=0},
		{name="air", prob=0},
		{name="air", prob=0},
		{name="air", prob=0},

		{name="air", prob=0},
		{name="air", prob=0},
		{name="air", prob=0},
		{name="air", prob=0},
		{name="air", prob=0},

		{name="air", prob=0},
		{name="air", prob=0},
		{name="air", prob=0},
		{name="air", prob=0},
		{name="air", prob=0},

		{name="air", prob=0},
		{name="air", prob=0},
		{name="air", prob=0},
		{name="air", prob=0},
		{name="air", prob=0},

		{name="air", prob=0},
		{name="air", prob=0},
		{name="air", prob=0},
		{name="air", prob=0},
		{name="air", prob=0},

		{name="default:pine_needles", prob=191},
		{name="default:pine_needles", prob=223},
		{name="default:pine_needles", prob=255},
		{name="default:pine_needles", prob=223},
		{name="default:pine_needles", prob=191},

		{name="air", prob=0},
		{name="air", prob=0},
		{name="air", prob=0},
		{name="air", prob=0},
		{name="air", prob=0},

		{name="air", prob=0},
		{name="air", prob=0},
		{name="air", prob=0},
		{name="air", prob=0},
		{name="air", prob=0},

		{name="default:pine_needles", prob=191},
		{name="default:pine_needles", prob=223},
		{name="default:pine_needles", prob=255},
		{name="default:pine_needles", prob=223},
		{name="default:pine_needles", prob=191},

		{name="air", prob=0},
		{name="air", prob=0},
		{name="air", prob=0},
		{name="air", prob=0},
		{name="air", prob=0},

		{name="air", prob=0},
		{name="air", prob=0},
		{name="air", prob=0},
		{name="air", prob=0},
		{name="air", prob=0},

		{name="default:pine_needles", prob=191},
		{name="default:pine_needles", prob=223},
		{name="default:pine_needles", prob=255},
		{name="default:pine_needles", prob=223},
		{name="default:pine_needles", prob=191},

		{name="air", prob=0},
		{name="air", prob=0},
		{name="air", prob=0},
		{name="air", prob=0},
		{name="air", prob=0},

		{name="air", prob=0},
		{name="air", prob=0},
		{name="air", prob=0},
		{name="air", prob=0},
		{name="air", prob=0},
	},
	yslice_prob = {
		{ypos=2, prob=127},
		{ypos=3, prob=127},
		{ypos=7, prob=127},
		{ypos=10, prob=127},
	},
})

-- Pine tree from sapling
mts_save("pine_tree_from_sapling", {
	size = {x=5, y=14, z=5},
	data = {-- -2

		{name="air", prob=0},
		{name="air", prob=0},
		{name="air", prob=0},
		{name="air", prob=0},
		{name="air", prob=0},

		{name="air", prob=0},
		{name="air", prob=0},
		{name="air", prob=0},
		{name="air", prob=0},
		{name="air", prob=0},

		{name="air", prob=0},
		{name="air", prob=0},
		{name="air", prob=0},
		{name="air", prob=0},
		{name="air", prob=0},

		{name="air", prob=0},
		{name="air", prob=0},
		{name="air", prob=0},
		{name="air", prob=0},
		{name="air", prob=0},

		{name="air", prob=0},
		{name="air", prob=0},
		{name="air", prob=0},
		{name="air", prob=0},
		{name="air", prob=0},

		{name="default:pine_needles", prob=191},
		{name="default:pine_needles", prob=223},
		{name="default:pine_needles", prob=255},
		{name="default:pine_needles", prob=223},
		{name="default:pine_needles", prob=191},

		{name="air", prob=0},
		{name="air", prob=0},
		{name="air", prob=0},
		{name="air", prob=0},
		{name="air", prob=0},

		{name="air", prob=0},
		{name="air", prob=0},
		{name="air", prob=0},
		{name="air", prob=0},
		{name="air", prob=0},

		{name="default:pine_needles", prob=191},
		{name="default:pine_needles", prob=223},
		{name="default:pine_needles", prob=255},
		{name="default:pine_needles", prob=223},
		{name="default:pine_needles", prob=191},

		{name="air", prob=0},
		{name="air", prob=0},
		{name="air", prob=0},
		{name="air", prob=0},
		{name="air", prob=0},

		{name="air", prob=0},
		{name="air", prob=0},
		{name="air", prob=0},
		{name="air", prob=0},
		{name="air", prob=0},

		{name="default:pine_needles", prob=191},
		{name="default:pine_needles", prob=223},
		{name="default:pine_needles", prob=255},
		{name="default:pine_needles", prob=223},
		{name="default:pine_needles", prob=191},

		{name="air", prob=0},
		{name="air", prob=0},
		{name="air", prob=0},
		{name="air", prob=0},
		{name="air", prob=0},

		{name="air", prob=0},
		{name="air", prob=0},
		{name="air", prob=0},
		{name="air", prob=0},
		{name="air", prob=0},

		-- -1

		{name="air", prob=0},
		{name="air", prob=0},
		{name="air", prob=0},
		{name="air", prob=0},
		{name="air", prob=0},

		{name="air", prob=0},
		{name="air", prob=0},
		{name="air", prob=0},
		{name="air", prob=0},
		{name="air", prob=0},

		{name="air", prob=0},
		{name="air", prob=0},
		{name="air", prob=0},
		{name="air", prob=0},
		{name="air", prob=0},

		{name="air", prob=0},
		{name="air", prob=0},
		{name="air", prob=0},
		{name="air", prob=0},
		{name="air", prob=0},

		{name="air", prob=0},
		{name="air", prob=0},
		{name="air", prob=0},
		{name="air", prob=0},
		{name="air", prob=0},

		{name="default:pine_needles", prob=223},
		{name="default:pine_needles", prob=255},
		{name="air", prob=0},
		{name="default:pine_needles", prob=255},
		{name="default:pine_needles", prob=223},

		{name="air", prob=0},
		{name="default:pine_needles", prob=255},
		{name="default:pine_needles", prob=255},
		{name="default:pine_needles", prob=255},
		{name="air", prob=0},

		{name="air", prob=0},
		{name="air", prob=0},
		{name="air", prob=0},
		{name="air", prob=0},
		{name="air", prob=0},

		{name="default:pine_needles", prob=223},
		{name="default:pine_needles", prob=255},
		{name="air", prob=0},
		{name="default:pine_needles", prob=255},
		{name="default:pine_needles", prob=223},

		{name="air", prob=0},
		{name="default:pine_needles", prob=255},
		{name="default:pine_needles", prob=255},
		{name="default:pine_needles", prob=255},
		{name="air", prob=0},

		{name="air", prob=0},
		{name="air", prob=0},
		{name="air", prob=0},
		{name="air", prob=0},
		{name="air", prob=0},

		{name="default:pine_needles", prob=223},
		{name="default:pine_needles", prob=255},
		{name="air", prob=0},
		{name="default:pine_needles", prob=255},
		{name="default:pine_needles", prob=223},

		{name="air", prob=0},
		{name="default:pine_needles", prob=255},
		{name="default:pine_needles", prob=255},
		{name="default:pine_needles", prob=255},
		{name="air", prob=0},

		{name="air", prob=0},
		{name="air", prob=0},
		{name="air", prob=0},
		{name="air", prob=0},
		{name="air", prob=0},

		-- 0

		{name="air", prob=0},
		{name="air", prob=0},
		{name="default:pine_tree", prob=255},
		{name="air", prob=0},
		{name="air", prob=0},

		{name="air", prob=0},
		{name="air", prob=0},
		{name="default:pine_tree", prob=255, force_place = true},
		{name="air", prob=0},
		{name="air", prob=0},

		{name="air", prob=0},
		{name="air", prob=0},
		{name="default:pine_tree", prob=255},
		{name="air", prob=0},
		{name="air", prob=0},

		{name="air", prob=0},
		{name="air", prob=0},
		{name="default:pine_tree", prob=255},
		{name="air", prob=0},
		{name="air", prob=0},

		{name="air", prob=0},
		{name="air", prob=0},
		{name="default:pine_tree", prob=255},
		{name="air", prob=0},
		{name="air", prob=0},

		{name="default:pine_needles", prob=255},
		{name="air", prob=0},
		{name="default:pine_tree", prob=255},
		{name="air", prob=0},
		{name="default:pine_needles", prob=255},

		{name="air", prob=0},
		{name="default:pine_needles", prob=255},
		{name="default:pine_tree", prob=255},
		{name="default:pine_needles", prob=255},
		{name="air", prob=0},

		{name="air", prob=0},
		{name="air", prob=0},
		{name="default:pine_tree", prob=255},
		{name="air", prob=0},
		{name="air", prob=0},

		{name="default:pine_needles", prob=255},
		{name="air", prob=0},
		{name="default:pine_tree", prob=255},
		{name="air", prob=0},
		{name="default:pine_needles", prob=255},

		{name="air", prob=0},
		{name="default:pine_needles", prob=255},
		{name="default:pine_tree", prob=255},
		{name="default:pine_needles", prob=255},
		{name="air", prob=0},

		{name="air", prob=0},
		{name="air", prob=0},
		{name="default:pine_tree", prob=255},
		{name="air", prob=0},
		{name="air", prob=0},

		{name="default:pine_needles", prob=255},
		{name="air", prob=0},
		{name="default:pine_tree", prob=255},
		{name="air", prob=0},
		{name="default:pine_needles", prob=255},

		{name="air", prob=0},
		{name="default:pine_needles", prob=255},
		{name="default:pine_needles", prob=255},
		{name="default:pine_needles", prob=255},
		{name="air", prob=0},

		{name="air", prob=0},
		{name="air", prob=0},
		{name="default:pine_needles", prob=255},
		{name="air", prob=0},
		{name="air", prob=0},

		-- 1

		{name="air", prob=0},
		{name="air", prob=0},
		{name="air", prob=0},
		{name="air", prob=0},
		{name="air", prob=0},

		{name="air", prob=0},
		{name="air", prob=0},
		{name="air", prob=0},
		{name="air", prob=0},
		{name="air", prob=0},

		{name="air", prob=0},
		{name="air", prob=0},
		{name="air", prob=0},
		{name="air", prob=0},
		{name="air", prob=0},

		{name="air", prob=0},
		{name="air", prob=0},
		{name="air", prob=0},
		{name="air", prob=0},
		{name="air", prob=0},

		{name="air", prob=0},
		{name="air", prob=0},
		{name="air", prob=0},
		{name="air", prob=0},
		{name="air", prob=0},

		{name="default:pine_needles", prob=223},
		{name="default:pine_needles", prob=255},
		{name="air", prob=0},
		{name="default:pine_needles", prob=255},
		{name="default:pine_needles", prob=223},

		{name="air", prob=0},
		{name="default:pine_needles", prob=255},
		{name="default:pine_needles", prob=255},
		{name="default:pine_needles", prob=255},
		{name="air", prob=0},

		{name="air", prob=0},
		{name="air", prob=0},
		{name="air", prob=0},
		{name="air", prob=0},
		{name="air", prob=0},

		{name="default:pine_needles", prob=223},
		{name="default:pine_needles", prob=255},
		{name="air", prob=0},
		{name="default:pine_needles", prob=255},
		{name="default:pine_needles", prob=223},

		{name="air", prob=0},
		{name="default:pine_needles", prob=255},
		{name="default:pine_needles", prob=255},
		{name="default:pine_needles", prob=255},
		{name="air", prob=0},

		{name="air", prob=0},
		{name="air", prob=0},
		{name="air", prob=0},
		{name="air", prob=0},
		{name="air", prob=0},

		{name="default:pine_needles", prob=223},
		{name="default:pine_needles", prob=255},
		{name="air", prob=0},
		{name="default:pine_needles", prob=255},
		{name="default:pine_needles", prob=223},

		{name="air", prob=0},
		{name="default:pine_needles", prob=255},
		{name="default:pine_needles", prob=255},
		{name="default:pine_needles", prob=255},
		{name="air", prob=0},

		{name="air", prob=0},
		{name="air", prob=0},
		{name="air", prob=0},
		{name="air", prob=0},
		{name="air", prob=0},

		-- 2

		{name="air", prob=0},
		{name="air", prob=0},
		{name="air", prob=0},
		{name="air", prob=0},
		{name="air", prob=0},

		{name="air", prob=0},
		{name="air", prob=0},
		{name="air", prob=0},
		{name="air", prob=0},
		{name="air", prob=0},

		{name="air", prob=0},
		{name="air", prob=0},
		{name="air", prob=0},
		{name="air", prob=0},
		{name="air", prob=0},

		{name="air", prob=0},
		{name="air", prob=0},
		{name="air", prob=0},
		{name="air", prob=0},
		{name="air", prob=0},

		{name="air", prob=0},
		{name="air", prob=0},
		{name="air", prob=0},
		{name="air", prob=0},
		{name="air", prob=0},

		{name="default:pine_needles", prob=191},
		{name="default:pine_needles", prob=223},
		{name="default:pine_needles", prob=255},
		{name="default:pine_needles", prob=223},
		{name="default:pine_needles", prob=191},

		{name="air", prob=0},
		{name="air", prob=0},
		{name="air", prob=0},
		{name="air", prob=0},
		{name="air", prob=0},

		{name="air", prob=0},
		{name="air", prob=0},
		{name="air", prob=0},
		{name="air", prob=0},
		{name="air", prob=0},

		{name="default:pine_needles", prob=191},
		{name="default:pine_needles", prob=223},
		{name="default:pine_needles", prob=255},
		{name="default:pine_needles", prob=223},
		{name="default:pine_needles", prob=191},

		{name="air", prob=0},
		{name="air", prob=0},
		{name="air", prob=0},
		{name="air", prob=0},
		{name="air", prob=0},

		{name="air", prob=0},
		{name="air", prob=0},
		{name="air", prob=0},
		{name="air", prob=0},
		{name="air", prob=0},

		{name="default:pine_needles", prob=191},
		{name="default:pine_needles", prob=223},
		{name="default:pine_needles", prob=255},
		{name="default:pine_needles", prob=223},
		{name="default:pine_needles", prob=191},

		{name="air", prob=0},
		{name="air", prob=0},
		{name="air", prob=0},
		{name="air", prob=0},
		{name="air", prob=0},

		{name="air", prob=0},
		{name="air", prob=0},
		{name="air", prob=0},
		{name="air", prob=0},
		{name="air", prob=0},
	},
	yslice_prob = {
		{ypos=2, prob=127},
		{ypos=3, prob=127},
		{ypos=7, prob=127},
		{ypos=10, prob=127},
	},
})

-- Acacia tree
mts_save("acacia_tree", {
	size = {x=9, y=8, z=9},
	data = {-- -4

		{name="air", prob=0},
		{name="air", prob=0},
		{name="air", prob=0},
		{name="air", prob=0},
		{name="air", prob=0},
		{name="air", prob=0},
		{name="air", prob=0},
		{name="air", prob=0},
		{name="air", prob=0},

		{name="air", prob=0},
		{name="air", prob=0},
		{name="air", prob=0},
		{name="air", prob=0},
		{name="air", prob=0},
		{name="air", prob=0},
		{name="air", prob=0},
		{name="air", prob=0},
		{name="air", prob=0},

		{name="air", prob=0},
		{name="air", prob=0},
		{name="air", prob=0},
		{name="air", prob=0},
		{name="air", prob=0},
		{name="air", prob=0},
		{name="air", prob=0},
		{name="air", prob=0},
		{name="air", prob=0},

		{name="air", prob=0},
		{name="air", prob=0},
		{name="air", prob=0},
		{name="air", prob=0},
		{name="air", prob=0},
		{name="air", prob=0},
		{name="air", prob=0},
		{name="air", prob=0},
		{name="air", prob=0},

		{name="air", prob=0},
		{name="air", prob=0},
		{name="air", prob=0},
		{name="air", prob=0},
		{name="air", prob=0},
		{name="air", prob=0},
		{name="air", prob=0},
		{name="air", prob=0},
		{name="air", prob=0},

		{name="air", prob=0},
		{name="air", prob=0},
		{name="air", prob=0},
		{name="air", prob=0},
		{name="air", prob=0},
		{name="air", prob=0},
		{name="air", prob=0},
		{name="air", prob=0},
		{name="air", prob=0},

		{name="default:acacia_leaves", prob=223},
		{name="default:acacia_leaves", prob=223},
		{name="default:acacia_leaves", prob=223},
		{name="default:acacia_leaves", prob=223},
		{name="air", prob=0},
		{name="air", prob=0},
		{name="air", prob=0},
		{name="air", prob=0},
		{name="air", prob=0},

		{name="air", prob=0},
		{name="air", prob=0},
		{name="air", prob=0},
		{name="air", prob=0},
		{name="default:acacia_leaves", prob=223},
		{name="default:acacia_leaves", prob=223},
		{name="default:acacia_leaves", prob=223},
		{name="default:acacia_leaves", prob=223},
		{name="default:acacia_leaves", prob=223},

		-- -3

		{name="air", prob=0},
		{name="air", prob=0},
		{name="air", prob=0},
		{name="air", prob=0},
		{name="air", prob=0},
		{name="air", prob=0},
		{name="air", prob=0},
		{name="air", prob=0},
		{name="air", prob=0},

		{name="air", prob=0},
		{name="air", prob=0},
		{name="air", prob=0},
		{name="air", prob=0},
		{name="air", prob=0},
		{name="air", prob=0},
		{name="air", prob=0},
		{name="air", prob=0},
		{name="air", prob=0},

		{name="air", prob=0},
		{name="air", prob=0},
		{name="air", prob=0},
		{name="air", prob=0},
		{name="air", prob=0},
		{name="air", prob=0},
		{name="air", prob=0},
		{name="air", prob=0},
		{name="air", prob=0},

		{name="air", prob=0},
		{name="air", prob=0},
		{name="air", prob=0},
		{name="air", prob=0},
		{name="air", prob=0},
		{name="air", prob=0},
		{name="air", prob=0},
		{name="air", prob=0},
		{name="air", prob=0},

		{name="air", prob=0},
		{name="air", prob=0},
		{name="air", prob=0},
		{name="air", prob=0},
		{name="air", prob=0},
		{name="air", prob=0},
		{name="air", prob=0},
		{name="air", prob=0},
		{name="air", prob=0},

		{name="air", prob=0},
		{name="air", prob=0},
		{name="air", prob=0},
		{name="air", prob=0},
		{name="air", prob=0},
		{name="air", prob=0},
		{name="air", prob=0},
		{name="air", prob=0},
		{name="air", prob=0},

		{name="default:acacia_leaves", prob=223},
		{name="default:acacia_leaves", prob=255},
		{name="default:acacia_leaves", prob=255},
		{name="default:acacia_leaves", prob=223},
		{name="air", prob=0},
		{name="air", prob=0},
		{name="air", prob=0},
		{name="air", prob=0},
		{name="air", prob=0},

		{name="air", prob=0},
		{name="air", prob=0},
		{name="air", prob=0},
		{name="air", prob=0},
		{name="default:acacia_leaves", prob=223},
		{name="default:acacia_leaves", prob=255},
		{name="default:acacia_leaves", prob=255},
		{name="default:acacia_leaves", prob=255},
		{name="default:acacia_leaves", prob=223},

		-- -2

		{name="air", prob=0},
		{name="air", prob=0},
		{name="air", prob=0},
		{name="air", prob=0},
		{name="air", prob=0},
		{name="air", prob=0},
		{name="air", prob=0},
		{name="air", prob=0},
		{name="air", prob=0},

		{name="air", prob=0},
		{name="air", prob=0},
		{name="air", prob=0},
		{name="air", prob=0},
		{name="air", prob=0},
		{name="air", prob=0},
		{name="air", prob=0},
		{name="air", prob=0},
		{name="air", prob=0},

		{name="air", prob=0},
		{name="air", prob=0},
		{name="air", prob=0},
		{name="air", prob=0},
		{name="air", prob=0},
		{name="air", prob=0},
		{name="air", prob=0},
		{name="air", prob=0},
		{name="air", prob=0},

		{name="air", prob=0},
		{name="air", prob=0},
		{name="air", prob=0},
		{name="air", prob=0},
		{name="air", prob=0},
		{name="air", prob=0},
		{name="air", prob=0},
		{name="air", prob=0},
		{name="air", prob=0},

		{name="air", prob=0},
		{name="air", prob=0},
		{name="air", prob=0},
		{name="air", prob=0},
		{name="air", prob=0},
		{name="air", prob=0},
		{name="air", prob=0},
		{name="air", prob=0},
		{name="air", prob=0},

		{name="air", prob=0},
		{name="air", prob=0},
		{name="default:acacia_tree", prob=255, force_place = true},
		{name="air", prob=0},
		{name="air", prob=0},
		{name="air", prob=0},
		{name="air", prob=0},
		{name="air", prob=0},
		{name="air", prob=0},

		{name="default:acacia_leaves", prob=223},
		{name="default:acacia_leaves", prob=255},
		{name="default:acacia_leaves", prob=255},
		{name="default:acacia_leaves", prob=223},
		{name="air", prob=0},
		{name="air", prob=0},
		{name="default:acacia_tree", prob=255, force_place = true},
		{name="air", prob=0},
		{name="air", prob=0},

		{name="air", prob=0},
		{name="air", prob=0},
		{name="air", prob=0},
		{name="air", prob=0},
		{name="default:acacia_leaves", prob=223},
		{name="default:acacia_leaves", prob=255},
		{name="default:acacia_leaves", prob=255},
		{name="default:acacia_leaves", prob=255},
		{name="default:acacia_leaves", prob=223},

		-- -1

		{name="air", prob=0},
		{name="air", prob=0},
		{name="air", prob=0},
		{name="air", prob=0},
		{name="air", prob=0},
		{name="air", prob=0},
		{name="air", prob=0},
		{name="air", prob=0},
		{name="air", prob=0},

		{name="air", prob=0},
		{name="air", prob=0},
		{name="air", prob=0},
		{name="air", prob=0},
		{name="air", prob=0},
		{name="air", prob=0},
		{name="air", prob=0},
		{name="air", prob=0},
		{name="air", prob=0},

		{name="air", prob=0},
		{name="air", prob=0},
		{name="air", prob=0},
		{name="air", prob=0},
		{name="air", prob=0},
		{name="air", prob=0},
		{name="air", prob=0},
		{name="air", prob=0},
		{name="air", prob=0},

		{name="air", prob=0},
		{name="air", prob=0},
		{name="air", prob=0},
		{name="air", prob=0},
		{name="air", prob=0},
		{name="air", prob=0},
		{name="air", prob=0},
		{name="air", prob=0},
		{name="air", prob=0},

		{name="air", prob=0},
		{name="air", prob=0},
		{name="air", prob=0},
		{name="default:acacia_tree", prob=255, force_place = true},
		{name="air", prob=0},
		{name="air", prob=0},
		{name="air", prob=0},
		{name="air", prob=0},
		{name="air", prob=0},

		{name="air", prob=0},
		{name="air", prob=0},
		{name="air", prob=0},
		{name="air", prob=0},
		{name="air", prob=0},
		{name="default:acacia_tree", prob=255, force_place = true},
		{name="air", prob=0},
		{name="air", prob=0},
		{name="air", prob=0},

		{name="default:acacia_leaves", prob=223},
		{name="default:acacia_leaves", prob=223},
		{name="default:acacia_leaves", prob=223},
		{name="default:acacia_leaves", prob=223},
		{name="air", prob=0},
		{name="air", prob=0},
		{name="air", prob=0},
		{name="air", prob=0},
		{name="air", prob=0},

		{name="air", prob=0},
		{name="air", prob=0},
		{name="air", prob=0},
		{name="air", prob=0},
		{name="default:acacia_leaves", prob=223},
		{name="default:acacia_leaves", prob=255},
		{name="default:acacia_leaves", prob=255},
		{name="default:acacia_leaves", prob=255},
		{name="default:acacia_leaves", prob=223},

		-- 0

		{name="air", prob=0},
		{name="air", prob=0},
		{name="air", prob=0},
		{name="air", prob=0},
		{name="default:acacia_tree", prob=255, force_place = true},
		{name="air", prob=0},
		{name="air", prob=0},
		{name="air", prob=0},
		{name="air", prob=0},

		{name="air", prob=0},
		{name="air", prob=0},
		{name="air", prob=0},
		{name="air", prob=0},
		{name="default:acacia_tree", prob=255, force_place = true},
		{name="air", prob=0},
		{name="air", prob=0},
		{name="air", prob=0},
		{name="air", prob=0},

		{name="air", prob=0},
		{name="air", prob=0},
		{name="air", prob=0},
		{name="air", prob=0},
		{name="default:acacia_tree", prob=255, force_place = true},
		{name="air", prob=0},
		{name="air", prob=0},
		{name="air", prob=0},
		{name="air", prob=0},

		{name="air", prob=0},
		{name="air", prob=0},
		{name="air", prob=0},
		{name="air", prob=0},
		{name="default:acacia_tree", prob=255, force_place = true},
		{name="air", prob=0},
		{name="air", prob=0},
		{name="air", prob=0},
		{name="air", prob=0},

		{name="air", prob=0},
		{name="air", prob=0},
		{name="air", prob=0},
		{name="air", prob=0},
		{name="default:acacia_tree", prob=255, force_place = true},
		{name="air", prob=0},
		{name="air", prob=0},
		{name="air", prob=0},
		{name="air", prob=0},

		{name="air", prob=0},
		{name="air", prob=0},
		{name="air", prob=0},
		{name="air", prob=0},
		{name="air", prob=0},
		{name="air", prob=0},
		{name="air", prob=0},
		{name="air", prob=0},
		{name="air", prob=0},

		{name="air", prob=0},
		{name="air", prob=0},
		{name="air", prob=0},
		{name="air", prob=0},
		{name="air", prob=0},
		{name="air", prob=0},
		{name="air", prob=0},
		{name="air", prob=0},
		{name="air", prob=0},

		{name="default:acacia_leaves", prob=223},
		{name="default:acacia_leaves", prob=223},
		{name="default:acacia_leaves", prob=223},
		{name="default:acacia_leaves", prob=223},
		{name="default:acacia_leaves", prob=223},
		{name="default:acacia_leaves", prob=223},
		{name="default:acacia_leaves", prob=223},
		{name="default:acacia_leaves", prob=223},
		{name="default:acacia_leaves", prob=223},

		-- 1

		{name="air", prob=0},
		{name="air", prob=0},
		{name="air", prob=0},
		{name="air", prob=0},
		{name="air", prob=0},
		{name="air", prob=0},
		{name="air", prob=0},
		{name="air", prob=0},
		{name="air", prob=0},

		{name="air", prob=0},
		{name="air", prob=0},
		{name="air", prob=0},
		{name="air", prob=0},
		{name="air", prob=0},
		{name="air", prob=0},
		{name="air", prob=0},
		{name="air", prob=0},
		{name="air", prob=0},

		{name="air", prob=0},
		{name="air", prob=0},
		{name="air", prob=0},
		{name="air", prob=0},
		{name="air", prob=0},
		{name="air", prob=0},
		{name="air", prob=0},
		{name="air", prob=0},
		{name="air", prob=0},

		{name="air", prob=0},
		{name="air", prob=0},
		{name="air", prob=0},
		{name="air", prob=0},
		{name="air", prob=0},
		{name="air", prob=0},
		{name="air", prob=0},
		{name="air", prob=0},
		{name="air", prob=0},

		{name="air", prob=0},
		{name="air", prob=0},
		{name="air", prob=0},
		{name="air", prob=0},
		{name="air", prob=0},
		{name="default:acacia_tree", prob=255, force_place = true},
		{name="air", prob=0},
		{name="air", prob=0},
		{name="air", prob=0},

		{name="air", prob=0},
		{name="air", prob=0},
		{name="air", prob=0},
		{name="default:acacia_tree", prob=255, force_place = true},
		{name="air", prob=0},
		{name="air", prob=0},
		{name="air", prob=0},
		{name="air", prob=0},
		{name="air", prob=0},

		{name="air", prob=0},
		{name="air", prob=0},
		{name="air", prob=0},
		{name="air", prob=0},
		{name="air", prob=0},
		{name="default:acacia_leaves", prob=223},
		{name="default:acacia_leaves", prob=223},
		{name="default:acacia_leaves", prob=223},
		{name="default:acacia_leaves", prob=223},

		{name="default:acacia_leaves", prob=223},
		{name="default:acacia_leaves", prob=255},
		{name="default:acacia_leaves", prob=255},
		{name="default:acacia_leaves", prob=255},
		{name="default:acacia_leaves", prob=223},
		{name="air", prob=0},
		{name="air", prob=0},
		{name="air", prob=0},
		{name="air", prob=0},

		-- 2

		{name="air", prob=0},
		{name="air", prob=0},
		{name="air", prob=0},
		{name="air", prob=0},
		{name="air", prob=0},
		{name="air", prob=0},
		{name="air", prob=0},
		{name="air", prob=0},
		{name="air", prob=0},

		{name="air", prob=0},
		{name="air", prob=0},
		{name="air", prob=0},
		{name="air", prob=0},
		{name="air", prob=0},
		{name="air", prob=0},
		{name="air", prob=0},
		{name="air", prob=0},
		{name="air", prob=0},

		{name="air", prob=0},
		{name="air", prob=0},
		{name="air", prob=0},
		{name="air", prob=0},
		{name="air", prob=0},
		{name="air", prob=0},
		{name="air", prob=0},
		{name="air", prob=0},
		{name="air", prob=0},

		{name="air", prob=0},
		{name="air", prob=0},
		{name="air", prob=0},
		{name="air", prob=0},
		{name="air", prob=0},
		{name="air", prob=0},
		{name="air", prob=0},
		{name="air", prob=0},
		{name="air", prob=0},

		{name="air", prob=0},
		{name="air", prob=0},
		{name="air", prob=0},
		{name="air", prob=0},
		{name="air", prob=0},
		{name="air", prob=0},
		{name="air", prob=0},
		{name="air", prob=0},
		{name="air", prob=0},

		{name="air", prob=0},
		{name="air", prob=0},
		{name="air", prob=0},
		{name="air", prob=0},
		{name="air", prob=0},
		{name="air", prob=0},
		{name="default:acacia_tree", prob=255, force_place = true},
		{name="air", prob=0},
		{name="air", prob=0},

		{name="air", prob=0},
		{name="air", prob=0},
		{name="default:acacia_tree", prob=255, force_place = true},
		{name="air", prob=0},
		{name="air", prob=0},
		{name="default:acacia_leaves", prob=223},
		{name="default:acacia_leaves", prob=255},
		{name="default:acacia_leaves", prob=255},
		{name="default:acacia_leaves", prob=223},

		{name="default:acacia_leaves", prob=223},
		{name="default:acacia_leaves", prob=255},
		{name="default:acacia_leaves", prob=255},
		{name="default:acacia_leaves", prob=255},
		{name="default:acacia_leaves", prob=223},
		{name="air", prob=0},
		{name="air", prob=0},
		{name="air", prob=0},
		{name="air", prob=0},

		-- 3

		{name="air", prob=0},
		{name="air", prob=0},
		{name="air", prob=0},
		{name="air", prob=0},
		{name="air", prob=0},
		{name="air", prob=0},
		{name="air", prob=0},
		{name="air", prob=0},
		{name="air", prob=0},

		{name="air", prob=0},
		{name="air", prob=0},
		{name="air", prob=0},
		{name="air", prob=0},
		{name="air", prob=0},
		{name="air", prob=0},
		{name="air", prob=0},
		{name="air", prob=0},
		{name="air", prob=0},

		{name="air", prob=0},
		{name="air", prob=0},
		{name="air", prob=0},
		{name="air", prob=0},
		{name="air", prob=0},
		{name="air", prob=0},
		{name="air", prob=0},
		{name="air", prob=0},
		{name="air", prob=0},

		{name="air", prob=0},
		{name="air", prob=0},
		{name="air", prob=0},
		{name="air", prob=0},
		{name="air", prob=0},
		{name="air", prob=0},
		{name="air", prob=0},
		{name="air", prob=0},
		{name="air", prob=0},

		{name="air", prob=0},
		{name="air", prob=0},
		{name="air", prob=0},
		{name="air", prob=0},
		{name="air", prob=0},
		{name="air", prob=0},
		{name="air", prob=0},
		{name="air", prob=0},
		{name="air", prob=0},

		{name="air", prob=0},
		{name="air", prob=0},
		{name="air", prob=0},
		{name="air", prob=0},
		{name="air", prob=0},
		{name="air", prob=0},
		{name="air", prob=0},
		{name="air", prob=0},
		{name="air", prob=0},

		{name="air", prob=0},
		{name="air", prob=0},
		{name="air", prob=0},
		{name="air", prob=0},
		{name="air", prob=0},
		{name="default:acacia_leaves", prob=223},
		{name="default:acacia_leaves", prob=255},
		{name="default:acacia_leaves", prob=255},
		{name="default:acacia_leaves", prob=223},

		{name="default:acacia_leaves", prob=223},
		{name="default:acacia_leaves", prob=255},
		{name="default:acacia_leaves", prob=255},
		{name="default:acacia_leaves", prob=255},
		{name="default:acacia_leaves", prob=223},
		{name="air", prob=0},
		{name="air", prob=0},
		{name="air", prob=0},
		{name="air", prob=0},

		-- 4

		{name="air", prob=0},
		{name="air", prob=0},
		{name="air", prob=0},
		{name="air", prob=0},
		{name="air", prob=0},
		{name="air", prob=0},
		{name="air", prob=0},
		{name="air", prob=0},
		{name="air", prob=0},

		{name="air", prob=0},
		{name="air", prob=0},
		{name="air", prob=0},
		{name="air", prob=0},
		{name="air", prob=0},
		{name="air", prob=0},
		{name="air", prob=0},
		{name="air", prob=0},
		{name="air", prob=0},

		{name="air", prob=0},
		{name="air", prob=0},
		{name="air", prob=0},
		{name="air", prob=0},
		{name="air", prob=0},
		{name="air", prob=0},
		{name="air", prob=0},
		{name="air", prob=0},
		{name="air", prob=0},

		{name="air", prob=0},
		{name="air", prob=0},
		{name="air", prob=0},
		{name="air", prob=0},
		{name="air", prob=0},
		{name="air", prob=0},
		{name="air", prob=0},
		{name="air", prob=0},
		{name="air", prob=0},

		{name="air", prob=0},
		{name="air", prob=0},
		{name="air", prob=0},
		{name="air", prob=0},
		{name="air", prob=0},
		{name="air", prob=0},
		{name="air", prob=0},
		{name="air", prob=0},
		{name="air", prob=0},

		{name="air", prob=0},
		{name="air", prob=0},
		{name="air", prob=0},
		{name="air", prob=0},
		{name="air", prob=0},
		{name="air", prob=0},
		{name="air", prob=0},
		{name="air", prob=0},
		{name="air", prob=0},

		{name="air", prob=0},
		{name="air", prob=0},
		{name="air", prob=0},
		{name="air", prob=0},
		{name="air", prob=0},
		{name="default:acacia_leaves", prob=223},
		{name="default:acacia_leaves", prob=223},
		{name="default:acacia_leaves", prob=223},
		{name="default:acacia_leaves", prob=223},

		{name="default:acacia_leaves", prob=223},
		{name="default:acacia_leaves", prob=223},
		{name="default:acacia_leaves", prob=223},
		{name="default:acacia_leaves", prob=223},
		{name="default:acacia_leaves", prob=223},
		{name="air", prob=0},
		{name="air", prob=0},
		{name="air", prob=0},
		{name="air", prob=0},
	},
	yslice_prob = {
		{ypos=2, prob=127},
	},
})

-- Acacia tree from sapling
mts_save("acacia_tree_from_sapling", {
	size = {x=9, y=8, z=9},
	data = {-- -4

		{name="air", prob=0},
		{name="air", prob=0},
		{name="air", prob=0},
		{name="air", prob=0},
		{name="air", prob=0},
		{name="air", prob=0},
		{name="air", prob=0},
		{name="air", prob=0},
		{name="air", prob=0},

		{name="air", prob=0},
		{name="air", prob=0},
		{name="air", prob=0},
		{name="air", prob=0},
		{name="air", prob=0},
		{name="air", prob=0},
		{name="air", prob=0},
		{name="air", prob=0},
		{name="air", prob=0},

		{name="air", prob=0},
		{name="air", prob=0},
		{name="air", prob=0},
		{name="air", prob=0},
		{name="air", prob=0},
		{name="air", prob=0},
		{name="air", prob=0},
		{name="air", prob=0},
		{name="air", prob=0},

		{name="air", prob=0},
		{name="air", prob=0},
		{name="air", prob=0},
		{name="air", prob=0},
		{name="air", prob=0},
		{name="air", prob=0},
		{name="air", prob=0},
		{name="air", prob=0},
		{name="air", prob=0},

		{name="air", prob=0},
		{name="air", prob=0},
		{name="air", prob=0},
		{name="air", prob=0},
		{name="air", prob=0},
		{name="air", prob=0},
		{name="air", prob=0},
		{name="air", prob=0},
		{name="air", prob=0},

		{name="air", prob=0},
		{name="air", prob=0},
		{name="air", prob=0},
		{name="air", prob=0},
		{name="air", prob=0},
		{name="air", prob=0},
		{name="air", prob=0},
		{name="air", prob=0},
		{name="air", prob=0},

		{name="default:acacia_leaves", prob=223},
		{name="default:acacia_leaves", prob=223},
		{name="default:acacia_leaves", prob=223},
		{name="default:acacia_leaves", prob=223},
		{name="air", prob=0},
		{name="air", prob=0},
		{name="air", prob=0},
		{name="air", prob=0},
		{name="air", prob=0},

		{name="air", prob=0},
		{name="air", prob=0},
		{name="air", prob=0},
		{name="air", prob=0},
		{name="default:acacia_leaves", prob=223},
		{name="default:acacia_leaves", prob=223},
		{name="default:acacia_leaves", prob=223},
		{name="default:acacia_leaves", prob=223},
		{name="default:acacia_leaves", prob=223},

		-- -3

		{name="air", prob=0},
		{name="air", prob=0},
		{name="air", prob=0},
		{name="air", prob=0},
		{name="air", prob=0},
		{name="air", prob=0},
		{name="air", prob=0},
		{name="air", prob=0},
		{name="air", prob=0},

		{name="air", prob=0},
		{name="air", prob=0},
		{name="air", prob=0},
		{name="air", prob=0},
		{name="air", prob=0},
		{name="air", prob=0},
		{name="air", prob=0},
		{name="air", prob=0},
		{name="air", prob=0},

		{name="air", prob=0},
		{name="air", prob=0},
		{name="air", prob=0},
		{name="air", prob=0},
		{name="air", prob=0},
		{name="air", prob=0},
		{name="air", prob=0},
		{name="air", prob=0},
		{name="air", prob=0},

		{name="air", prob=0},
		{name="air", prob=0},
		{name="air", prob=0},
		{name="air", prob=0},
		{name="air", prob=0},
		{name="air", prob=0},
		{name="air", prob=0},
		{name="air", prob=0},
		{name="air", prob=0},

		{name="air", prob=0},
		{name="air", prob=0},
		{name="air", prob=0},
		{name="air", prob=0},
		{name="air", prob=0},
		{name="air", prob=0},
		{name="air", prob=0},
		{name="air", prob=0},
		{name="air", prob=0},

		{name="air", prob=0},
		{name="air", prob=0},
		{name="air", prob=0},
		{name="air", prob=0},
		{name="air", prob=0},
		{name="air", prob=0},
		{name="air", prob=0},
		{name="air", prob=0},
		{name="air", prob=0},

		{name="default:acacia_leaves", prob=223},
		{name="default:acacia_leaves", prob=255},
		{name="default:acacia_leaves", prob=255},
		{name="default:acacia_leaves", prob=223},
		{name="air", prob=0},
		{name="air", prob=0},
		{name="air", prob=0},
		{name="air", prob=0},
		{name="air", prob=0},

		{name="air", prob=0},
		{name="air", prob=0},
		{name="air", prob=0},
		{name="air", prob=0},
		{name="default:acacia_leaves", prob=223},
		{name="default:acacia_leaves", prob=255},
		{name="default:acacia_leaves", prob=255},
		{name="default:acacia_leaves", prob=255},
		{name="default:acacia_leaves", prob=223},

		-- -2

		{name="air", prob=0},
		{name="air", prob=0},
		{name="air", prob=0},
		{name="air", prob=0},
		{name="air", prob=0},
		{name="air", prob=0},
		{name="air", prob=0},
		{name="air", prob=0},
		{name="air", prob=0},

		{name="air", prob=0},
		{name="air", prob=0},
		{name="air", prob=0},
		{name="air", prob=0},
		{name="air", prob=0},
		{name="air", prob=0},
		{name="air", prob=0},
		{name="air", prob=0},
		{name="air", prob=0},

		{name="air", prob=0},
		{name="air", prob=0},
		{name="air", prob=0},
		{name="air", prob=0},
		{name="air", prob=0},
		{name="air", prob=0},
		{name="air", prob=0},
		{name="air", prob=0},
		{name="air", prob=0},

		{name="air", prob=0},
		{name="air", prob=0},
		{name="air", prob=0},
		{name="air", prob=0},
		{name="air", prob=0},
		{name="air", prob=0},
		{name="air", prob=0},
		{name="air", prob=0},
		{name="air", prob=0},

		{name="air", prob=0},
		{name="air", prob=0},
		{name="air", prob=0},
		{name="air", prob=0},
		{name="air", prob=0},
		{name="air", prob=0},
		{name="air", prob=0},
		{name="air", prob=0},
		{name="air", prob=0},

		{name="air", prob=0},
		{name="air", prob=0},
		{name="default:acacia_tree", prob=255},
		{name="air", prob=0},
		{name="air", prob=0},
		{name="air", prob=0},
		{name="air", prob=0},
		{name="air", prob=0},
		{name="air", prob=0},

		{name="default:acacia_leaves", prob=223},
		{name="default:acacia_leaves", prob=255},
		{name="default:acacia_leaves", prob=255},
		{name="default:acacia_leaves", prob=223},
		{name="air", prob=0},
		{name="air", prob=0},
		{name="default:acacia_tree", prob=255},
		{name="air", prob=0},
		{name="air", prob=0},

		{name="air", prob=0},
		{name="air", prob=0},
		{name="air", prob=0},
		{name="air", prob=0},
		{name="default:acacia_leaves", prob=223},
		{name="default:acacia_leaves", prob=255},
		{name="default:acacia_leaves", prob=255},
		{name="default:acacia_leaves", prob=255},
		{name="default:acacia_leaves", prob=223},

		-- -1

		{name="air", prob=0},
		{name="air", prob=0},
		{name="air", prob=0},
		{name="air", prob=0},
		{name="air", prob=0},
		{name="air", prob=0},
		{name="air", prob=0},
		{name="air", prob=0},
		{name="air", prob=0},

		{name="air", prob=0},
		{name="air", prob=0},
		{name="air", prob=0},
		{name="air", prob=0},
		{name="air", prob=0},
		{name="air", prob=0},
		{name="air", prob=0},
		{name="air", prob=0},
		{name="air", prob=0},

		{name="air", prob=0},
		{name="air", prob=0},
		{name="air", prob=0},
		{name="air", prob=0},
		{name="air", prob=0},
		{name="air", prob=0},
		{name="air", prob=0},
		{name="air", prob=0},
		{name="air", prob=0},

		{name="air", prob=0},
		{name="air", prob=0},
		{name="air", prob=0},
		{name="air", prob=0},
		{name="air", prob=0},
		{name="air", prob=0},
		{name="air", prob=0},
		{name="air", prob=0},
		{name="air", prob=0},

		{name="air", prob=0},
		{name="air", prob=0},
		{name="air", prob=0},
		{name="default:acacia_tree", prob=255},
		{name="air", prob=0},
		{name="air", prob=0},
		{name="air", prob=0},
		{name="air", prob=0},
		{name="air", prob=0},

		{name="air", prob=0},
		{name="air", prob=0},
		{name="air", prob=0},
		{name="air", prob=0},
		{name="air", prob=0},
		{name="default:acacia_tree", prob=255},
		{name="air", prob=0},
		{name="air", prob=0},
		{name="air", prob=0},

		{name="default:acacia_leaves", prob=223},
		{name="default:acacia_leaves", prob=223},
		{name="default:acacia_leaves", prob=223},
		{name="default:acacia_leaves", prob=223},
		{name="air", prob=0},
		{name="air", prob=0},
		{name="air", prob=0},
		{name="air", prob=0},
		{name="air", prob=0},

		{name="air", prob=0},
		{name="air", prob=0},
		{name="air", prob=0},
		{name="air", prob=0},
		{name="default:acacia_leaves", prob=223},
		{name="default:acacia_leaves", prob=255},
		{name="default:acacia_leaves", prob=255},
		{name="default:acacia_leaves", prob=255},
		{name="default:acacia_leaves", prob=223},

		-- 0

		{name="air", prob=0},
		{name="air", prob=0},
		{name="air", prob=0},
		{name="air", prob=0},
		{name="default:acacia_tree", prob=255},
		{name="air", prob=0},
		{name="air", prob=0},
		{name="air", prob=0},
		{name="air", prob=0},

		{name="air", prob=0},
		{name="air", prob=0},
		{name="air", prob=0},
		{name="air", prob=0},
		{name="default:acacia_tree", prob=255, force_place = true},
		{name="air", prob=0},
		{name="air", prob=0},
		{name="air", prob=0},
		{name="air", prob=0},

		{name="air", prob=0},
		{name="air", prob=0},
		{name="air", prob=0},
		{name="air", prob=0},
		{name="default:acacia_tree", prob=255},
		{name="air", prob=0},
		{name="air", prob=0},
		{name="air", prob=0},
		{name="air", prob=0},

		{name="air", prob=0},
		{name="air", prob=0},
		{name="air", prob=0},
		{name="air", prob=0},
		{name="default:acacia_tree", prob=255},
		{name="air", prob=0},
		{name="air", prob=0},
		{name="air", prob=0},
		{name="air", prob=0},

		{name="air", prob=0},
		{name="air", prob=0},
		{name="air", prob=0},
		{name="air", prob=0},
		{name="default:acacia_tree", prob=255},
		{name="air", prob=0},
		{name="air", prob=0},
		{name="air", prob=0},
		{name="air", prob=0},

		{name="air", prob=0},
		{name="air", prob=0},
		{name="air", prob=0},
		{name="air", prob=0},
		{name="air", prob=0},
		{name="air", prob=0},
		{name="air", prob=0},
		{name="air", prob=0},
		{name="air", prob=0},

		{name="air", prob=0},
		{name="air", prob=0},
		{name="air", prob=0},
		{name="air", prob=0},
		{name="air", prob=0},
		{name="air", prob=0},
		{name="air", prob=0},
		{name="air", prob=0},
		{name="air", prob=0},

		{name="default:acacia_leaves", prob=223},
		{name="default:acacia_leaves", prob=223},
		{name="default:acacia_leaves", prob=223},
		{name="default:acacia_leaves", prob=223},
		{name="default:acacia_leaves", prob=223},
		{name="default:acacia_leaves", prob=223},
		{name="default:acacia_leaves", prob=223},
		{name="default:acacia_leaves", prob=223},
		{name="default:acacia_leaves", prob=223},

		-- 1

		{name="air", prob=0},
		{name="air", prob=0},
		{name="air", prob=0},
		{name="air", prob=0},
		{name="air", prob=0},
		{name="air", prob=0},
		{name="air", prob=0},
		{name="air", prob=0},
		{name="air", prob=0},

		{name="air", prob=0},
		{name="air", prob=0},
		{name="air", prob=0},
		{name="air", prob=0},
		{name="air", prob=0},
		{name="air", prob=0},
		{name="air", prob=0},
		{name="air", prob=0},
		{name="air", prob=0},

		{name="air", prob=0},
		{name="air", prob=0},
		{name="air", prob=0},
		{name="air", prob=0},
		{name="air", prob=0},
		{name="air", prob=0},
		{name="air", prob=0},
		{name="air", prob=0},
		{name="air", prob=0},

		{name="air", prob=0},
		{name="air", prob=0},
		{name="air", prob=0},
		{name="air", prob=0},
		{name="air", prob=0},
		{name="air", prob=0},
		{name="air", prob=0},
		{name="air", prob=0},
		{name="air", prob=0},

		{name="air", prob=0},
		{name="air", prob=0},
		{name="air", prob=0},
		{name="air", prob=0},
		{name="air", prob=0},
		{name="default:acacia_tree", prob=255},
		{name="air", prob=0},
		{name="air", prob=0},
		{name="air", prob=0},

		{name="air", prob=0},
		{name="air", prob=0},
		{name="air", prob=0},
		{name="default:acacia_tree", prob=255},
		{name="air", prob=0},
		{name="air", prob=0},
		{name="air", prob=0},
		{name="air", prob=0},
		{name="air", prob=0},

		{name="air", prob=0},
		{name="air", prob=0},
		{name="air", prob=0},
		{name="air", prob=0},
		{name="air", prob=0},
		{name="default:acacia_leaves", prob=223},
		{name="default:acacia_leaves", prob=223},
		{name="default:acacia_leaves", prob=223},
		{name="default:acacia_leaves", prob=223},

		{name="default:acacia_leaves", prob=223},
		{name="default:acacia_leaves", prob=255},
		{name="default:acacia_leaves", prob=255},
		{name="default:acacia_leaves", prob=255},
		{name="default:acacia_leaves", prob=223},
		{name="air", prob=0},
		{name="air", prob=0},
		{name="air", prob=0},
		{name="air", prob=0},

		-- 2

		{name="air", prob=0},
		{name="air", prob=0},
		{name="air", prob=0},
		{name="air", prob=0},
		{name="air", prob=0},
		{name="air", prob=0},
		{name="air", prob=0},
		{name="air", prob=0},
		{name="air", prob=0},

		{name="air", prob=0},
		{name="air", prob=0},
		{name="air", prob=0},
		{name="air", prob=0},
		{name="air", prob=0},
		{name="air", prob=0},
		{name="air", prob=0},
		{name="air", prob=0},
		{name="air", prob=0},

		{name="air", prob=0},
		{name="air", prob=0},
		{name="air", prob=0},
		{name="air", prob=0},
		{name="air", prob=0},
		{name="air", prob=0},
		{name="air", prob=0},
		{name="air", prob=0},
		{name="air", prob=0},

		{name="air", prob=0},
		{name="air", prob=0},
		{name="air", prob=0},
		{name="air", prob=0},
		{name="air", prob=0},
		{name="air", prob=0},
		{name="air", prob=0},
		{name="air", prob=0},
		{name="air", prob=0},

		{name="air", prob=0},
		{name="air", prob=0},
		{name="air", prob=0},
		{name="air", prob=0},
		{name="air", prob=0},
		{name="air", prob=0},
		{name="air", prob=0},
		{name="air", prob=0},
		{name="air", prob=0},

		{name="air", prob=0},
		{name="air", prob=0},
		{name="air", prob=0},
		{name="air", prob=0},
		{name="air", prob=0},
		{name="air", prob=0},
		{name="default:acacia_tree", prob=255},
		{name="air", prob=0},
		{name="air", prob=0},

		{name="air", prob=0},
		{name="air", prob=0},
		{name="default:acacia_tree", prob=255},
		{name="air", prob=0},
		{name="air", prob=0},
		{name="default:acacia_leaves", prob=223},
		{name="default:acacia_leaves", prob=255},
		{name="default:acacia_leaves", prob=255},
		{name="default:acacia_leaves", prob=223},

		{name="default:acacia_leaves", prob=223},
		{name="default:acacia_leaves", prob=255},
		{name="default:acacia_leaves", prob=255},
		{name="default:acacia_leaves", prob=255},
		{name="default:acacia_leaves", prob=223},
		{name="air", prob=0},
		{name="air", prob=0},
		{name="air", prob=0},
		{name="air", prob=0},

		-- 3

		{name="air", prob=0},
		{name="air", prob=0},
		{name="air", prob=0},
		{name="air", prob=0},
		{name="air", prob=0},
		{name="air", prob=0},
		{name="air", prob=0},
		{name="air", prob=0},
		{name="air", prob=0},

		{name="air", prob=0},
		{name="air", prob=0},
		{name="air", prob=0},
		{name="air", prob=0},
		{name="air", prob=0},
		{name="air", prob=0},
		{name="air", prob=0},
		{name="air", prob=0},
		{name="air", prob=0},

		{name="air", prob=0},
		{name="air", prob=0},
		{name="air", prob=0},
		{name="air", prob=0},
		{name="air", prob=0},
		{name="air", prob=0},
		{name="air", prob=0},
		{name="air", prob=0},
		{name="air", prob=0},

		{name="air", prob=0},
		{name="air", prob=0},
		{name="air", prob=0},
		{name="air", prob=0},
		{name="air", prob=0},
		{name="air", prob=0},
		{name="air", prob=0},
		{name="air", prob=0},
		{name="air", prob=0},

		{name="air", prob=0},
		{name="air", prob=0},
		{name="air", prob=0},
		{name="air", prob=0},
		{name="air", prob=0},
		{name="air", prob=0},
		{name="air", prob=0},
		{name="air", prob=0},
		{name="air", prob=0},

		{name="air", prob=0},
		{name="air", prob=0},
		{name="air", prob=0},
		{name="air", prob=0},
		{name="air", prob=0},
		{name="air", prob=0},
		{name="air", prob=0},
		{name="air", prob=0},
		{name="air", prob=0},

		{name="air", prob=0},
		{name="air", prob=0},
		{name="air", prob=0},
		{name="air", prob=0},
		{name="air", prob=0},
		{name="default:acacia_leaves", prob=223},
		{name="default:acacia_leaves", prob=255},
		{name="default:acacia_leaves", prob=255},
		{name="default:acacia_leaves", prob=223},

		{name="default:acacia_leaves", prob=223},
		{name="default:acacia_leaves", prob=255},
		{name="default:acacia_leaves", prob=255},
		{name="default:acacia_leaves", prob=255},
		{name="default:acacia_leaves", prob=223},
		{name="air", prob=0},
		{name="air", prob=0},
		{name="air", prob=0},
		{name="air", prob=0},

		-- 4

		{name="air", prob=0},
		{name="air", prob=0},
		{name="air", prob=0},
		{name="air", prob=0},
		{name="air", prob=0},
		{name="air", prob=0},
		{name="air", prob=0},
		{name="air", prob=0},
		{name="air", prob=0},

		{name="air", prob=0},
		{name="air", prob=0},
		{name="air", prob=0},
		{name="air", prob=0},
		{name="air", prob=0},
		{name="air", prob=0},
		{name="air", prob=0},
		{name="air", prob=0},
		{name="air", prob=0},

		{name="air", prob=0},
		{name="air", prob=0},
		{name="air", prob=0},
		{name="air", prob=0},
		{name="air", prob=0},
		{name="air", prob=0},
		{name="air", prob=0},
		{name="air", prob=0},
		{name="air", prob=0},

		{name="air", prob=0},
		{name="air", prob=0},
		{name="air", prob=0},
		{name="air", prob=0},
		{name="air", prob=0},
		{name="air", prob=0},
		{name="air", prob=0},
		{name="air", prob=0},
		{name="air", prob=0},

		{name="air", prob=0},
		{name="air", prob=0},
		{name="air", prob=0},
		{name="air", prob=0},
		{name="air", prob=0},
		{name="air", prob=0},
		{name="air", prob=0},
		{name="air", prob=0},
		{name="air", prob=0},

		{name="air", prob=0},
		{name="air", prob=0},
		{name="air", prob=0},
		{name="air", prob=0},
		{name="air", prob=0},
		{name="air", prob=0},
		{name="air", prob=0},
		{name="air", prob=0},
		{name="air", prob=0},

		{name="air", prob=0},
		{name="air", prob=0},
		{name="air", prob=0},
		{name="air", prob=0},
		{name="air", prob=0},
		{name="default:acacia_leaves", prob=223},
		{name="default:acacia_leaves", prob=223},
		{name="default:acacia_leaves", prob=223},
		{name="default:acacia_leaves", prob=223},

		{name="default:acacia_leaves", prob=223},
		{name="default:acacia_leaves", prob=223},
		{name="default:acacia_leaves", prob=223},
		{name="default:acacia_leaves", prob=223},
		{name="default:acacia_leaves", prob=223},
		{name="air", prob=0},
		{name="air", prob=0},
		{name="air", prob=0},
		{name="air", prob=0},
	},
	yslice_prob = {
		{ypos=2, prob=127},
	},
})

-- Large cactus
mts_save("large_cactus", {
	size = {x=5, y=7, z=1},
	data = {
		{name="air", prob=0},
		{name="air", prob=0},
		{name="default:cactus", prob=255, param2=20, force_place = true},
		{name="air", prob=0},
		{name="air", prob=0},

		{name="air", prob=0},
		{name="air", prob=0},
		{name="default:cactus", prob=255, param2=20},
		{name="air", prob=0},
		{name="air", prob=0},

		{name="air", prob=0},
		{name="air", prob=0},
		{name="default:cactus", prob=255, param2=20},
		{name="air", prob=0},
		{name="air", prob=0},

		{name="default:cactus", prob=255, param2=20},
		{name="default:cactus", prob=255, param2=20},
		{name="default:cactus", prob=255, param2=20},
		{name="default:cactus", prob=255, param2=20},
		{name="default:cactus", prob=255, param2=20},

		{name="default:cactus", prob=255, param2=20},
		{name="air", prob=0},
		{name="default:cactus", prob=255, param2=20},
		{name="air", prob=0},
		{name="default:cactus", prob=255, param2=20},

		{name="default:cactus", prob=127, param2=20},
		{name="air", prob=0},
		{name="default:cactus", prob=255, param2=20},
		{name="air", prob=0},
		{name="default:cactus", prob=127, param2=20},

		{name="air", prob=0},
		{name="air", prob=0},
		{name="default:cactus", prob=255, param2=20},
		{name="air", prob=0},
		{name="air", prob=0},
	},
})

-- Papyrus
mts_save("papyrus", {
	size = {x = 1, y = 7, z = 1},
	data = {
		{name = "default:sand", prob = 255, force_place = true},
		{name = "default:sand", prob = 255, force_place = true},
		{name = "default:papyrus", prob = 255},
		{name = "default:papyrus", prob = 255},
		{name = "default:papyrus", prob = 255},
		{name = "default:papyrus", prob = 255},
		{name = "default:papyrus", prob = 255},
	},
	yslice_prob = {
		{ypos = 2, prob = 127},
		{ypos = 3, prob = 127},
	},
})

